<sdf version='1.6'>
  <world name='default'>
    <light name='sun' type='directional'>
      <cast_shadows>1</cast_shadows>
      <pose frame=''>0 0 10 0 -0 0</pose>
      <diffuse>0.8 0.8 0.8 1</diffuse>
      <specular>0.1 0.1 0.1 1</specular>
      <attenuation>
        <range>1000</range>
        <constant>0.9</constant>
        <linear>0.01</linear>
        <quadratic>0.001</quadratic>
      </attenuation>
      <direction>-0.5 0.5 -1</direction>
    </light>
    <model name='ground_plane'>
      <static>1</static>
      <link name='link'>
        <collision name='collision'>
          <geometry>
            <plane>
              <normal>0 0 1</normal>
              <size>100 100</size>
            </plane>
          </geometry>
          <surface>
            <friction>
              <ode>
                <mu>100</mu>
                <mu2>50</mu2>
              </ode>
              <torsional>
                <ode/>
              </torsional>
            </friction>
            <contact>
              <ode/>
            </contact>
            <bounce/>
          </surface>
          <max_contacts>10</max_contacts>
        </collision>
        <visual name='visual'>
          <cast_shadows>0</cast_shadows>
          <geometry>
            <plane>
              <normal>0 0 1</normal>
              <size>100 100</size>
            </plane>
          </geometry>
          <material>
            <script>
              <uri>file://media/materials/scripts/gazebo.material</uri>
              <name>Gazebo/Grey</name>
            </script>
          </material>
        </visual>
        <self_collide>0</self_collide>
        <enable_wind>0</enable_wind>
        <kinematic>0</kinematic>
      </link>
    </model>
    <gravity>0 0 -9.8</gravity>
    <magnetic_field>6e-06 2.3e-05 -4.2e-05</magnetic_field>
    <atmosphere type='adiabatic'/>
    <physics name='default_physics' default='0' type='ode'>
      <max_step_size>0.001</max_step_size>
      <real_time_factor>1</real_time_factor>
      <real_time_update_rate>1000</real_time_update_rate>
    </physics>
    <scene>
      <ambient>0.4 0.4 0.4 1</ambient>
      <background>0.7 0.7 0.7 1</background>
      <shadows>1</shadows>
    </scene>
    <wind/>
    <spherical_coordinates>
      <surface_model>EARTH_WGS84</surface_model>
      <latitude_deg>0</latitude_deg>
      <longitude_deg>0</longitude_deg>
      <elevation>0</elevation>
      <heading_deg>0</heading_deg>
    </spherical_coordinates>
    <model name='pr2'>
      <static>0</static>
      <link name='base_footprint'>
        <self_collide>0</self_collide>
        <inertial>
          <mass>118.001</mass>
          <pose frame=''>-0.062421 0 0.201365 0 -0 0</pose>
          <inertia>
            <ixx>8.43173</ixx>
            <ixy>-0.00972</ixy>
            <ixz>1.90157</ixz>
            <iyy>8.53305</iyy>
            <iyz>-0.00738</iyz>
            <izz>3.78747</izz>
          </inertia>
        </inertial>
        <collision name='base_footprint_geom'>
          <pose frame=''>0 0 0.071 0 -0 0</pose>
          <geometry>
            <box>
              <size>0.001 0.001 0.001</size>
            </box>
          </geometry>
          <max_contacts>10</max_contacts>
          <surface>
            <contact>
              <ode/>
            </contact>
            <bounce/>
            <friction>
              <torsional>
                <ode/>
              </torsional>
              <ode/>
            </friction>
          </surface>
        </collision>
        <visual name='base_footprint_geom_visual'>
          <geometry>
            <box>
              <size>0.01 0.01 0.01</size>
            </box>
          </geometry>
        </visual>
        <collision name='base_footprint_geom_base_bellow_link'>
          <pose frame=''>-0.29 0 0.851 0 -0 0</pose>
          <geometry>
            <box>
              <size>0.05 0.37 0.3</size>
            </box>
          </geometry>
          <max_contacts>10</max_contacts>
          <surface>
            <contact>
              <ode/>
            </contact>
            <bounce/>
            <friction>
              <torsional>
                <ode/>
              </torsional>
              <ode/>
            </friction>
          </surface>
        </collision>
        <visual name='base_footprint_geom_base_bellow_link_visual'>
          <pose frame=''>-0.29 0 0.851 0 -0 0</pose>
          <geometry>
            <box>
              <size>0.05 0.37 0.3</size>
            </box>
          </geometry>
        </visual>
        <collision name='base_footprint_geom_base_link'>
          <pose frame=''>0 0 0.051 0 -0 0</pose>
          <geometry>
            <mesh>
              <uri>model://pr2/meshes/base_v0/base_L.stl</uri>
              <scale>1 1 1</scale>
            </mesh>
          </geometry>
          <max_contacts>10</max_contacts>
          <surface>
            <contact>
              <ode/>
            </contact>
            <bounce/>
            <friction>
              <torsional>
                <ode/>
              </torsional>
              <ode/>
            </friction>
          </surface>
        </collision>
        <visual name='base_footprint_geom_base_link_visual'>
          <pose frame=''>0 0 0.051 0 -0 0</pose>
          <geometry>
            <mesh>
              <uri>model://pr2/meshes/base_v0/base.dae</uri>
              <scale>1 1 1</scale>
            </mesh>
          </geometry>
        </visual>
        <sensor name='base_contact_sensor' type='contact'>
          <update_rate>100</update_rate>
          <contact>
            <collision>base_footprint_geom_base_link</collision>
            <topic>__default_topic__</topic>
          </contact>
          <plugin name='gazebo_contact' filename='libContactPlugin.so'/>
        </sensor>
        <sensor name='base_laser' type='ray'>
          <always_on>1</always_on>
          <visualize>1</visualize>
          <update_rate>20</update_rate>
          <pose frame=''>0.275 0 0.303 0 -0 0</pose>
          <ray>
            <scan>
              <horizontal>
                <samples>640</samples>
                <resolution>1</resolution>
                <min_angle>-2.2689</min_angle>
                <max_angle>2.2689</max_angle>
              </horizontal>
              <vertical>
                <samples>1</samples>
                <min_angle>0</min_angle>
                <max_angle>0</max_angle>
              </vertical>
            </scan>
            <range>
              <min>0.08</min>
              <max>10</max>
              <resolution>0.01</resolution>
            </range>
          </ray>
          <plugin name='laser' filename='libRayPlugin.so'/>
        </sensor>
        <velocity_decay/>
        <enable_wind>0</enable_wind>
        <kinematic>0</kinematic>
      </link>
      <link name='bl_caster_rotation_link'>
        <self_collide>0</self_collide>
        <pose frame=''>-0.2246 0.2246 0.0792 0 -0 0</pose>
        <inertial>
          <mass>3.47308</mass>
          <pose frame=''>0 0 0.07 0 -0 0</pose>
          <inertia>
            <ixx>0.012412</ixx>
            <ixy>-0.000712</ixy>
            <ixz>0.000503</ixz>
            <iyy>0.015218</iyy>
            <iyz>-4e-06</iyz>
            <izz>0.011764</izz>
          </inertia>
        </inertial>
        <collision name='bl_caster_rotation_link_geom'>
          <geometry>
            <mesh>
              <uri>model://pr2/meshes/base_v0/caster_L.stl</uri>
              <scale>1 1 1</scale>
            </mesh>
          </geometry>
          <max_contacts>10</max_contacts>
          <surface>
            <contact>
              <ode/>
            </contact>
            <bounce/>
            <friction>
              <torsional>
                <ode/>
              </torsional>
              <ode/>
            </friction>
          </surface>
        </collision>
        <visual name='bl_caster_rotation_link_geom_visual'>
          <geometry>
            <mesh>
              <uri>model://pr2/meshes/base_v0/caster.stl</uri>
              <scale>1 1 1</scale>
            </mesh>
          </geometry>
        </visual>
        <velocity_decay/>
        <enable_wind>0</enable_wind>
        <kinematic>0</kinematic>
      </link>
      <link name='bl_caster_l_wheel_link'>
        <self_collide>0</self_collide>
        <pose frame=''>-0.2246 0.2736 0.0792 0 -0 0</pose>
        <inertial>
          <mass>0.44036</mass>
          <inertia>
            <ixx>0.012412</ixx>
            <ixy>-0.000712</ixy>
            <ixz>0.000503</ixz>
            <iyy>0.015218</iyy>
            <iyz>-4e-06</iyz>
            <izz>0.011764</izz>
          </inertia>
        </inertial>
        <collision name='bl_caster_l_wheel_link_geom'>
          <pose frame=''>0 0 0 1.5708 -0 0</pose>
          <geometry>
            <cylinder>
              <radius>0.074792</radius>
              <length>0.034</length>
            </cylinder>
          </geometry>
          <max_contacts>10</max_contacts>
          <surface>
            <contact>
              <ode/>
            </contact>
            <bounce/>
            <friction>
              <torsional>
                <ode/>
              </torsional>
              <ode/>
            </friction>
          </surface>
        </collision>
        <visual name='bl_caster_l_wheel_link_geom_visual'>
          <geometry>
            <mesh>
              <uri>model://pr2/meshes/base_v0/wheel.dae</uri>
              <scale>1 1 1</scale>
            </mesh>
          </geometry>
        </visual>
        <velocity_decay/>
        <enable_wind>0</enable_wind>
        <kinematic>0</kinematic>
      </link>
      <link name='bl_caster_r_wheel_link'>
        <self_collide>0</self_collide>
        <pose frame=''>-0.2246 0.1756 0.0792 0 -0 0</pose>
        <inertial>
          <mass>0.44036</mass>
          <inertia>
            <ixx>0.012412</ixx>
            <ixy>0.000712</ixy>
            <ixz>0.000503</ixz>
            <iyy>0.015218</iyy>
            <iyz>4e-06</iyz>
            <izz>0.011764</izz>
          </inertia>
        </inertial>
        <collision name='bl_caster_r_wheel_link_geom'>
          <pose frame=''>0 0 0 1.5708 -0 0</pose>
          <geometry>
            <cylinder>
              <radius>0.074792</radius>
              <length>0.034</length>
            </cylinder>
          </geometry>
          <max_contacts>10</max_contacts>
          <surface>
            <contact>
              <ode/>
            </contact>
            <bounce/>
            <friction>
              <torsional>
                <ode/>
              </torsional>
              <ode/>
            </friction>
          </surface>
        </collision>
        <visual name='bl_caster_r_wheel_link_geom_visual'>
          <geometry>
            <mesh>
              <uri>model://pr2/meshes/base_v0/wheel.dae</uri>
              <scale>1 1 1</scale>
            </mesh>
          </geometry>
        </visual>
        <velocity_decay/>
        <enable_wind>0</enable_wind>
        <kinematic>0</kinematic>
      </link>
      <link name='br_caster_rotation_link'>
        <self_collide>0</self_collide>
        <pose frame=''>-0.2246 -0.2246 0.0792 0 -0 0</pose>
        <inertial>
          <mass>3.47308</mass>
          <pose frame=''>0 0 0.07 0 -0 0</pose>
          <inertia>
            <ixx>0.012412</ixx>
            <ixy>-0.000712</ixy>
            <ixz>0.000503</ixz>
            <iyy>0.015218</iyy>
            <iyz>-4e-06</iyz>
            <izz>0.011764</izz>
          </inertia>
        </inertial>
        <collision name='br_caster_rotation_link_geom'>
          <geometry>
            <mesh>
              <uri>model://pr2/meshes/base_v0/caster_L.stl</uri>
              <scale>1 1 1</scale>
            </mesh>
          </geometry>
          <max_contacts>10</max_contacts>
          <surface>
            <contact>
              <ode/>
            </contact>
            <bounce/>
            <friction>
              <torsional>
                <ode/>
              </torsional>
              <ode/>
            </friction>
          </surface>
        </collision>
        <visual name='br_caster_rotation_link_geom_visual'>
          <geometry>
            <mesh>
              <uri>model://pr2/meshes/base_v0/caster.stl</uri>
              <scale>1 1 1</scale>
            </mesh>
          </geometry>
        </visual>
        <velocity_decay/>
        <enable_wind>0</enable_wind>
        <kinematic>0</kinematic>
      </link>
      <link name='br_caster_l_wheel_link'>
        <self_collide>0</self_collide>
        <pose frame=''>-0.2246 -0.1756 0.0792 0 -0 0</pose>
        <inertial>
          <mass>0.44036</mass>
          <inertia>
            <ixx>0.012412</ixx>
            <ixy>-0.000712</ixy>
            <ixz>0.000503</ixz>
            <iyy>0.015218</iyy>
            <iyz>-4e-06</iyz>
            <izz>0.011764</izz>
          </inertia>
        </inertial>
        <collision name='br_caster_l_wheel_link_geom'>
          <pose frame=''>0 0 0 1.5708 -0 0</pose>
          <geometry>
            <cylinder>
              <radius>0.074792</radius>
              <length>0.034</length>
            </cylinder>
          </geometry>
          <max_contacts>10</max_contacts>
          <surface>
            <contact>
              <ode/>
            </contact>
            <bounce/>
            <friction>
              <torsional>
                <ode/>
              </torsional>
              <ode/>
            </friction>
          </surface>
        </collision>
        <visual name='br_caster_l_wheel_link_geom_visual'>
          <geometry>
            <mesh>
              <uri>model://pr2/meshes/base_v0/wheel.dae</uri>
              <scale>1 1 1</scale>
            </mesh>
          </geometry>
        </visual>
        <velocity_decay/>
        <enable_wind>0</enable_wind>
        <kinematic>0</kinematic>
      </link>
      <link name='br_caster_r_wheel_link'>
        <self_collide>0</self_collide>
        <pose frame=''>-0.2246 -0.2736 0.0792 0 -0 0</pose>
        <inertial>
          <mass>0.44036</mass>
          <inertia>
            <ixx>0.012412</ixx>
            <ixy>-0.000712</ixy>
            <ixz>0.000503</ixz>
            <iyy>0.015218</iyy>
            <iyz>-4e-06</iyz>
            <izz>0.011764</izz>
          </inertia>
        </inertial>
        <collision name='br_caster_r_wheel_link_geom'>
          <pose frame=''>0 0 0 1.5708 -0 0</pose>
          <geometry>
            <cylinder>
              <radius>0.074792</radius>
              <length>0.034</length>
            </cylinder>
          </geometry>
          <max_contacts>10</max_contacts>
          <surface>
            <contact>
              <ode/>
            </contact>
            <bounce/>
            <friction>
              <torsional>
                <ode/>
              </torsional>
              <ode/>
            </friction>
          </surface>
        </collision>
        <visual name='br_caster_r_wheel_link_geom_visual'>
          <geometry>
            <mesh>
              <uri>model://pr2/meshes/base_v0/wheel.dae</uri>
              <scale>1 1 1</scale>
            </mesh>
          </geometry>
        </visual>
        <velocity_decay/>
        <enable_wind>0</enable_wind>
        <kinematic>0</kinematic>
      </link>
      <link name='fl_caster_rotation_link'>
        <self_collide>0</self_collide>
        <pose frame=''>0.2246 0.2246 0.0792 0 -0 0</pose>
        <inertial>
          <mass>3.47308</mass>
          <pose frame=''>0 0 0.07 0 -0 0</pose>
          <inertia>
            <ixx>0.012412</ixx>
            <ixy>-0.000712</ixy>
            <ixz>0.000503</ixz>
            <iyy>0.015218</iyy>
            <iyz>-4e-06</iyz>
            <izz>0.011764</izz>
          </inertia>
        </inertial>
        <collision name='fl_caster_rotation_link_geom'>
          <geometry>
            <mesh>
              <uri>model://pr2/meshes/base_v0/caster_L.stl</uri>
              <scale>1 1 1</scale>
            </mesh>
          </geometry>
          <max_contacts>10</max_contacts>
          <surface>
            <contact>
              <ode/>
            </contact>
            <bounce/>
            <friction>
              <torsional>
                <ode/>
              </torsional>
              <ode/>
            </friction>
          </surface>
        </collision>
        <visual name='fl_caster_rotation_link_geom_visual'>
          <geometry>
            <mesh>
              <uri>model://pr2/meshes/base_v0/caster.stl</uri>
              <scale>1 1 1</scale>
            </mesh>
          </geometry>
        </visual>
        <velocity_decay/>
        <enable_wind>0</enable_wind>
        <kinematic>0</kinematic>
      </link>
      <link name='fl_caster_l_wheel_link'>
        <self_collide>0</self_collide>
        <pose frame=''>0.2246 0.2736 0.0792 0 -0 0</pose>
        <inertial>
          <mass>0.44036</mass>
          <inertia>
            <ixx>0.012412</ixx>
            <ixy>-0.000712</ixy>
            <ixz>0.000503</ixz>
            <iyy>0.015218</iyy>
            <iyz>-4e-06</iyz>
            <izz>0.011764</izz>
          </inertia>
        </inertial>
        <collision name='fl_caster_l_wheel_link_geom'>
          <pose frame=''>0 0 0 1.5708 -0 0</pose>
          <geometry>
            <cylinder>
              <radius>0.074792</radius>
              <length>0.034</length>
            </cylinder>
          </geometry>
          <max_contacts>10</max_contacts>
          <surface>
            <contact>
              <ode/>
            </contact>
            <bounce/>
            <friction>
              <torsional>
                <ode/>
              </torsional>
              <ode/>
            </friction>
          </surface>
        </collision>
        <visual name='fl_caster_l_wheel_link_geom_visual'>
          <geometry>
            <mesh>
              <uri>model://pr2/meshes/base_v0/wheel.dae</uri>
              <scale>1 1 1</scale>
            </mesh>
          </geometry>
        </visual>
        <velocity_decay/>
        <enable_wind>0</enable_wind>
        <kinematic>0</kinematic>
      </link>
      <link name='fl_caster_r_wheel_link'>
        <self_collide>0</self_collide>
        <pose frame=''>0.2246 0.1756 0.0792 0 -0 0</pose>
        <inertial>
          <mass>0.44036</mass>
          <inertia>
            <ixx>0.012412</ixx>
            <ixy>-0.000712</ixy>
            <ixz>0.000503</ixz>
            <iyy>0.015218</iyy>
            <iyz>-4e-06</iyz>
            <izz>0.011764</izz>
          </inertia>
        </inertial>
        <collision name='fl_caster_r_wheel_link_geom'>
          <pose frame=''>0 0 0 1.5708 -0 0</pose>
          <geometry>
            <cylinder>
              <radius>0.074792</radius>
              <length>0.034</length>
            </cylinder>
          </geometry>
          <max_contacts>10</max_contacts>
          <surface>
            <contact>
              <ode/>
            </contact>
            <bounce/>
            <friction>
              <torsional>
                <ode/>
              </torsional>
              <ode/>
            </friction>
          </surface>
        </collision>
        <visual name='fl_caster_r_wheel_link_geom_visual'>
          <geometry>
            <mesh>
              <uri>model://pr2/meshes/base_v0/wheel.dae</uri>
              <scale>1 1 1</scale>
            </mesh>
          </geometry>
        </visual>
        <velocity_decay/>
        <enable_wind>0</enable_wind>
        <kinematic>0</kinematic>
      </link>
      <link name='fr_caster_rotation_link'>
        <self_collide>0</self_collide>
        <pose frame=''>0.2246 -0.2246 0.0792 0 -0 0</pose>
        <inertial>
          <mass>3.47308</mass>
          <pose frame=''>0 0 0.07 0 -0 0</pose>
          <inertia>
            <ixx>0.012412</ixx>
            <ixy>-0.000712</ixy>
            <ixz>0.000503</ixz>
            <iyy>0.015218</iyy>
            <iyz>-4e-06</iyz>
            <izz>0.011764</izz>
          </inertia>
        </inertial>
        <collision name='fr_caster_rotation_link_geom'>
          <geometry>
            <mesh>
              <uri>model://pr2/meshes/base_v0/caster_L.stl</uri>
              <scale>1 1 1</scale>
            </mesh>
          </geometry>
          <max_contacts>10</max_contacts>
          <surface>
            <contact>
              <ode/>
            </contact>
            <bounce/>
            <friction>
              <torsional>
                <ode/>
              </torsional>
              <ode/>
            </friction>
          </surface>
        </collision>
        <visual name='fr_caster_rotation_link_geom_visual'>
          <geometry>
            <mesh>
              <uri>model://pr2/meshes/base_v0/caster.stl</uri>
              <scale>1 1 1</scale>
            </mesh>
          </geometry>
        </visual>
        <velocity_decay/>
        <enable_wind>0</enable_wind>
        <kinematic>0</kinematic>
      </link>
      <link name='fr_caster_l_wheel_link'>
        <self_collide>0</self_collide>
        <pose frame=''>0.2246 -0.1756 0.0792 0 -0 0</pose>
        <inertial>
          <mass>0.44036</mass>
          <inertia>
            <ixx>0.012412</ixx>
            <ixy>-0.000712</ixy>
            <ixz>0.000503</ixz>
            <iyy>0.015218</iyy>
            <iyz>-4e-06</iyz>
            <izz>0.011764</izz>
          </inertia>
        </inertial>
        <collision name='fr_caster_l_wheel_link_geom'>
          <pose frame=''>0 0 0 1.5708 -0 0</pose>
          <geometry>
            <cylinder>
              <radius>0.074792</radius>
              <length>0.034</length>
            </cylinder>
          </geometry>
          <max_contacts>10</max_contacts>
          <surface>
            <contact>
              <ode/>
            </contact>
            <bounce/>
            <friction>
              <torsional>
                <ode/>
              </torsional>
              <ode/>
            </friction>
          </surface>
        </collision>
        <visual name='fr_caster_l_wheel_link_geom_visual'>
          <geometry>
            <mesh>
              <uri>model://pr2/meshes/base_v0/wheel.dae</uri>
              <scale>1 1 1</scale>
            </mesh>
          </geometry>
        </visual>
        <velocity_decay/>
        <enable_wind>0</enable_wind>
        <kinematic>0</kinematic>
      </link>
      <link name='fr_caster_r_wheel_link'>
        <self_collide>0</self_collide>
        <pose frame=''>0.2246 -0.2736 0.0792 0 -0 0</pose>
        <inertial>
          <mass>0.44036</mass>
          <inertia>
            <ixx>0.012412</ixx>
            <ixy>-0.000712</ixy>
            <ixz>0.000503</ixz>
            <iyy>0.015218</iyy>
            <iyz>-4e-06</iyz>
            <izz>0.011764</izz>
          </inertia>
        </inertial>
        <collision name='fr_caster_r_wheel_link_geom'>
          <pose frame=''>0 0 0 1.5708 -0 0</pose>
          <geometry>
            <cylinder>
              <radius>0.074792</radius>
              <length>0.034</length>
            </cylinder>
          </geometry>
          <max_contacts>10</max_contacts>
          <surface>
            <contact>
              <ode/>
            </contact>
            <bounce/>
            <friction>
              <torsional>
                <ode/>
              </torsional>
              <ode/>
            </friction>
          </surface>
        </collision>
        <visual name='fr_caster_r_wheel_link_geom_visual'>
          <geometry>
            <mesh>
              <uri>model://pr2/meshes/base_v0/wheel.dae</uri>
              <scale>1 1 1</scale>
            </mesh>
          </geometry>
        </visual>
        <velocity_decay/>
        <enable_wind>0</enable_wind>
        <kinematic>0</kinematic>
      </link>
      <link name='torso_lift_link'>
        <self_collide>0</self_collide>
        <pose frame=''>-0.05 0 0.790675 0 -0 0</pose>
        <inertial>
          <mass>36.449</mass>
          <pose frame=''>-0.099499 -4e-06 -0.086764 0 -0 0</pose>
          <inertia>
            <ixx>2.79233</ixx>
            <ixy>0.00428</ixy>
            <ixz>-0.160631</ixz>
            <iyy>2.52106</iyy>
            <iyz>0.029689</iyz>
            <izz>0.536551</izz>
          </inertia>
        </inertial>
        <collision name='torso_lift_link_geom'>
          <geometry>
            <mesh>
              <uri>model://pr2/meshes/torso_v0/torso_lift_L.stl</uri>
              <scale>1 1 1</scale>
            </mesh>
          </geometry>
          <max_contacts>10</max_contacts>
          <surface>
            <contact>
              <ode/>
            </contact>
            <bounce/>
            <friction>
              <torsional>
                <ode/>
              </torsional>
              <ode/>
            </friction>
          </surface>
        </collision>
        <visual name='torso_lift_link_geom_visual'>
          <geometry>
            <mesh>
              <uri>model://pr2/meshes/torso_v0/torso_lift.dae</uri>
              <scale>1 1 1</scale>
            </mesh>
          </geometry>
        </visual>
        <sensor name='torso_lift_contact_sensor' type='contact'>
          <update_rate>100</update_rate>
          <contact>
            <collision>torso_lift_link_geom</collision>
            <topic>__default_topic__</topic>
          </contact>
        </sensor>
        <velocity_decay/>
        <enable_wind>0</enable_wind>
        <kinematic>0</kinematic>
      </link>
      <link name='head_pan_link'>
        <self_collide>0</self_collide>
        <pose frame=''>-0.06707 0 1.17213 0 -0 0</pose>
        <inertial>
          <mass>6.339</mass>
          <pose frame=''>0.010907 0.031693 0.090507 0 -0 0</pose>
          <inertia>
            <ixx>0.032498</ixx>
            <ixy>0.000636</ixy>
            <ixz>0.002585</ixz>
            <iyy>0.046546</iyy>
            <iyz>-0.002453</iyz>
            <izz>0.057653</izz>
          </inertia>
        </inertial>
        <collision name='head_pan_link_geom'>
          <geometry>
            <mesh>
              <uri>model://pr2/meshes/head_v0/head_pan_L.stl</uri>
              <scale>1 1 1</scale>
            </mesh>
          </geometry>
          <max_contacts>10</max_contacts>
          <surface>
            <contact>
              <ode/>
            </contact>
            <bounce/>
            <friction>
              <torsional>
                <ode/>
              </torsional>
              <ode/>
            </friction>
          </surface>
        </collision>
        <visual name='head_pan_link_geom_visual'>
          <geometry>
            <mesh>
              <uri>model://pr2/meshes/head_v0/head_pan.dae</uri>
              <scale>1 1 1</scale>
            </mesh>
          </geometry>
        </visual>
        <velocity_decay/>
        <enable_wind>0</enable_wind>
        <kinematic>0</kinematic>
      </link>
      <link name='head_tilt_link'>
        <projector name='projector_wg6802418_projector_wg6802418'>
          <texture>stereo_projection_pattern_high_res_red.png</texture>
          <fov>0.959931</fov>
          <near_clip>0.1</near_clip>
          <far_clip>10</far_clip>
          <pose frame=''>0.0232 0.11 0.1191 0 -1.57079 0</pose>
        </projector>
        <self_collide>0</self_collide>
        <pose frame=''>0.00093 0 1.17213 0 -0 0</pose>
        <inertial>
          <mass>5.319</mass>
          <pose frame=''>-0.005151 -0.014635 0.072819 0 -0 0</pose>
          <inertia>
            <ixx>0.126134</ixx>
            <ixy>0.000237</ixy>
            <ixz>0.011881</ixz>
            <iyy>0.165102</iyy>
            <iyz>0.001606</iyz>
            <izz>0.166947</izz>
          </inertia>
        </inertial>
        <collision name='head_tilt_link_geom'>
          <geometry>
            <mesh>
              <uri>model://pr2/meshes/head_v0/head_tilt_L.stl</uri>
              <scale>1 1 1</scale>
            </mesh>
          </geometry>
          <max_contacts>10</max_contacts>
          <surface>
            <contact>
              <ode/>
            </contact>
            <bounce/>
            <friction>
              <torsional>
                <ode/>
              </torsional>
              <ode/>
            </friction>
          </surface>
        </collision>
        <visual name='head_tilt_link_geom_visual'>
          <geometry>
            <mesh>
              <uri>model://pr2/meshes/head_v0/head_tilt.dae</uri>
              <scale>1 1 1</scale>
            </mesh>
          </geometry>
        </visual>
        <collision name='head_tilt_link_geom_head_mount_kinect_ir_link'>
          <pose frame=''>-0.147067 0.0125 0.291953 0 -0 0</pose>
          <geometry>
            <sphere>
              <radius>0.0005</radius>
            </sphere>
          </geometry>
          <max_contacts>10</max_contacts>
          <surface>
            <contact>
              <ode/>
            </contact>
            <bounce/>
            <friction>
              <torsional>
                <ode/>
              </torsional>
              <ode/>
            </friction>
          </surface>
        </collision>
        <visual name='head_tilt_link_geom_head_mount_kinect_ir_link_visual'>
          <pose frame=''>-0.147067 0.0125 0.291953 0 -0 0</pose>
          <geometry>
            <sphere>
              <radius>0.00025</radius>
            </sphere>
          </geometry>
          <material>
            <script>
              <name>Gazebo/Red</name>
              <uri>__default__</uri>
            </script>
          </material>
        </visual>
        <collision name='head_tilt_link_geom_head_mount_kinect_rgb_link'>
          <pose frame=''>-0.147067 0.0175 0.291953 0 -0 0</pose>
          <geometry>
            <sphere>
              <radius>0.0005</radius>
            </sphere>
          </geometry>
          <max_contacts>10</max_contacts>
          <surface>
            <contact>
              <ode/>
            </contact>
            <bounce/>
            <friction>
              <torsional>
                <ode/>
              </torsional>
              <ode/>
            </friction>
          </surface>
        </collision>
        <visual name='head_tilt_link_geom_head_mount_kinect_rgb_link_visual'>
          <pose frame=''>-0.147067 0.0175 0.291953 0 -0 0</pose>
          <geometry>
            <sphere>
              <radius>0.00025</radius>
            </sphere>
          </geometry>
          <material>
            <script>
              <name>Gazebo/Red</name>
              <uri>__default__</uri>
            </script>
          </material>
        </visual>
        <collision name='head_tilt_link_geom_head_mount_link'>
          <pose frame=''>-0.1148 0 0.1555 0 -0 0</pose>
          <geometry>
            <sphere>
              <radius>0.0005</radius>
            </sphere>
          </geometry>
          <max_contacts>10</max_contacts>
          <surface>
            <contact>
              <ode/>
            </contact>
            <bounce/>
            <friction>
              <torsional>
                <ode/>
              </torsional>
              <ode/>
            </friction>
          </surface>
        </collision>
        <visual name='head_tilt_link_geom_head_mount_link_visual'>
          <pose frame=''>-0.1148 0 0.1555 0 -0 0</pose>
          <geometry>
            <mesh>
              <uri>model://pr2/meshes/sensors/kinect_prosilica_v0/115x100_swept_back--coarse.STL</uri>
              <scale>1 1 1</scale>
            </mesh>
          </geometry>
        </visual>
        <collision name='head_tilt_link_geom_head_mount_prosilica_link'>
          <pose frame=''>-0.161257 0.0125 0.244421 0 -0 0</pose>
          <geometry>
            <sphere>
              <radius>0.0005</radius>
            </sphere>
          </geometry>
          <max_contacts>10</max_contacts>
          <surface>
            <contact>
              <ode/>
            </contact>
            <bounce/>
            <friction>
              <torsional>
                <ode/>
              </torsional>
              <ode/>
            </friction>
          </surface>
        </collision>
        <visual name='head_tilt_link_geom_head_mount_prosilica_link_visual'>
          <pose frame=''>-0.161257 0.0125 0.244421 0 -0 0</pose>
          <geometry>
            <sphere>
              <radius>0.00025</radius>
            </sphere>
          </geometry>
          <material>
            <script>
              <name>Gazebo/Red</name>
              <uri>__default__</uri>
            </script>
          </material>
        </visual>
        <collision name='head_tilt_link_geom_head_plate_frame'>
          <pose frame=''>0.0232 0 0.0645 0 -0 0</pose>
          <geometry>
            <box>
              <size>0.01 0.01 0.01</size>
            </box>
          </geometry>
          <max_contacts>10</max_contacts>
          <surface>
            <contact>
              <ode/>
            </contact>
            <bounce/>
            <friction>
              <torsional>
                <ode/>
              </torsional>
              <ode/>
            </friction>
          </surface>
        </collision>
        <visual name='head_tilt_link_geom_head_plate_frame_visual'>
          <pose frame=''>0.0232 0 0.0645 0 -0 0</pose>
          <geometry>
            <box>
              <size>0.01 0.01 0.01</size>
            </box>
          </geometry>
          <material>
            <script>
              <name>Gazebo/Grey</name>
              <uri>__default__</uri>
            </script>
          </material>
        </visual>
        <sensor name='head_mount_sensor' type='camera'>
          <always_on>0</always_on>
          <visualize>0</visualize>
          <update_rate>1</update_rate>
          <pose frame=''>-0.147067 0.0125 0.291953 0 -0 0</pose>
          <camera name='__default__'>
            <horizontal_fov>0.994838</horizontal_fov>
            <image>
              <width>640</width>
              <height>480</height>
              <format>L8</format>
            </image>
            <clip>
              <near>0.01</near>
              <far>5</far>
            </clip>
          </camera>
        </sensor>
        <sensor name='head_mount_prosilica_link_sensor' type='camera'>
          <update_rate>1</update_rate>
          <pose frame=''>-0.161257 0.0125 0.244421 0 -0 0</pose>
          <camera name='__default__'>
            <horizontal_fov>1.1205</horizontal_fov>
            <image>
              <width>320</width>
              <height>240</height>
              <format>R8G8B8</format>
            </image>
            <clip>
              <near>0.1</near>
              <far>100</far>
            </clip>
          </camera>
        </sensor>
        <sensor name='head_mount_prosilica_link_sim_pcd_sensor' type='camera'>
          <update_rate>1</update_rate>
          <pose frame=''>-0.161257 0.0125 0.244421 0 -0 0</pose>
          <camera name='__default__'>
            <horizontal_fov>1.1205</horizontal_fov>
            <image>
              <width>320</width>
              <height>240</height>
              <format>R8G8B8</format>
            </image>
            <clip>
              <near>0.1</near>
              <far>100</far>
            </clip>
          </camera>
        </sensor>
        <sensor name='narrow_stereo_gazebo_l_stereo_camera_sensor' type='camera'>
          <always_on>1</always_on>
          <visualize>1</visualize>
          <update_rate>25</update_rate>
          <pose frame=''>0.0682 0.06 0.1146 0 -0 0</pose>
          <camera name='__default__'>
            <horizontal_fov>0.785398</horizontal_fov>
            <image>
              <width>640</width>
              <height>480</height>
              <format>L8</format>
            </image>
            <clip>
              <near>0.1</near>
              <far>100</far>
            </clip>
          </camera>
        </sensor>
        <sensor name='narrow_stereo_gazebo_r_stereo_camera_sensor' type='camera'>
          <always_on>1</always_on>
          <update_rate>25</update_rate>
          <pose frame=''>0.0682 -0.03 0.1146 0 -0 0</pose>
          <camera name='__default__'>
            <horizontal_fov>0.785398</horizontal_fov>
            <image>
              <width>640</width>
              <height>480</height>
              <format>L8</format>
            </image>
            <clip>
              <near>0.1</near>
              <far>100</far>
            </clip>
          </camera>
        </sensor>
        <sensor name='wide_stereo_gazebo_l_stereo_camera_sensor' type='camera'>
          <update_rate>25</update_rate>
          <pose frame=''>0.0682 0.03 0.1146 0 -0 0</pose>
          <camera name='__default__'>
            <horizontal_fov>1.5708</horizontal_fov>
            <image>
              <width>640</width>
              <height>480</height>
              <format>BAYER_BGGR8</format>
            </image>
            <clip>
              <near>0.1</near>
              <far>100</far>
            </clip>
          </camera>
        </sensor>
        <sensor name='wide_stereo_gazebo_r_stereo_camera_sensor' type='camera'>
          <update_rate>25</update_rate>
          <pose frame=''>0.0682 -0.06 0.1146 0 -0 0</pose>
          <camera name='__default__'>
            <horizontal_fov>1.5708</horizontal_fov>
            <image>
              <width>640</width>
              <height>480</height>
              <format>BAYER_BGGR8</format>
            </image>
            <clip>
              <near>0.1</near>
              <far>100</far>
            </clip>
          </camera>
        </sensor>
        <sensor name='high_def_sensor' type='camera'>
          <update_rate>20</update_rate>
          <pose frame=''>0.069657 -0.11 0.1191 0 -0 0</pose>
          <camera name='__default__'>
            <horizontal_fov>0.785398</horizontal_fov>
            <image>
              <width>2448</width>
              <height>2050</height>
              <format>R8G8B8</format>
            </image>
            <clip>
              <near>0.1</near>
              <far>100</far>
            </clip>
          </camera>
        </sensor>
        <velocity_decay/>
        <enable_wind>0</enable_wind>
        <kinematic>0</kinematic>
      </link>
      <link name='l_shoulder_pan_link'>
        <self_collide>0</self_collide>
        <gravity>0</gravity>
        <pose frame=''>-0.05 0.188 0.790675 0 -0 0</pose>
        <inertial>
          <mass>25.7993</mass>
          <pose frame=''>-0.001201 0.024513 -0.098231 0 -0 0</pose>
          <inertia>
            <ixx>0.866179</ixx>
            <ixy>-0.060865</ixy>
            <ixz>-0.121181</ixz>
            <iyy>0.874217</iyy>
            <iyz>-0.058866</iyz>
            <izz>0.273538</izz>
          </inertia>
        </inertial>
        <collision name='l_shoulder_pan_link_geom'>
          <geometry>
            <mesh>
              <uri>model://pr2/meshes/shoulder_v0/shoulder_pan.stl</uri>
              <scale>1 1 1</scale>
            </mesh>
          </geometry>
          <max_contacts>10</max_contacts>
          <surface>
            <contact>
              <ode/>
            </contact>
            <bounce/>
            <friction>
              <torsional>
                <ode/>
              </torsional>
              <ode/>
            </friction>
          </surface>
        </collision>
        <visual name='l_shoulder_pan_link_geom_visual'>
          <geometry>
            <mesh>
              <uri>model://pr2/meshes/shoulder_v0/shoulder_pan.dae</uri>
              <scale>1 1 1</scale>
            </mesh>
          </geometry>
        </visual>
        <velocity_decay/>
        <enable_wind>0</enable_wind>
        <kinematic>0</kinematic>
      </link>
      <link name='l_shoulder_lift_link'>
        <self_collide>0</self_collide>
        <gravity>0</gravity>
        <pose frame=''>0.05 0.188 0.790675 0 -0 0</pose>
        <inertial>
          <mass>2.74988</mass>
          <pose frame=''>0.02195 -0.02664 -0.03127 0 -0 0</pose>
          <inertia>
            <ixx>0.021056</ixx>
            <ixy>0.004967</ixy>
            <ixz>-0.001948</ixz>
            <iyy>0.021272</iyy>
            <iyz>0.001104</iyz>
            <izz>0.019758</izz>
          </inertia>
        </inertial>
        <collision name='l_shoulder_lift_link_geom'>
          <geometry>
            <mesh>
              <uri>model://pr2/meshes/shoulder_v0/shoulder_lift.stl</uri>
              <scale>1 1 1</scale>
            </mesh>
          </geometry>
          <max_contacts>10</max_contacts>
          <surface>
            <contact>
              <ode/>
            </contact>
            <bounce/>
            <friction>
              <torsional>
                <ode/>
              </torsional>
              <ode/>
            </friction>
          </surface>
        </collision>
        <visual name='l_shoulder_lift_link_geom_visual'>
          <geometry>
            <mesh>
              <uri>model://pr2/meshes/shoulder_v0/shoulder_lift.dae</uri>
              <scale>1 1 1</scale>
            </mesh>
          </geometry>
        </visual>
        <velocity_decay/>
        <enable_wind>0</enable_wind>
        <kinematic>0</kinematic>
      </link>
      <link name='l_upper_arm_roll_link'>
        <self_collide>0</self_collide>
        <gravity>0</gravity>
        <pose frame=''>0.05 0.188 0.790675 0 -0 0</pose>
        <inertial>
          <mass>6.11769</mass>
          <pose frame=''>0.210551 0.016309 -0.000561 0 -0 0</pose>
          <inertia>
            <ixx>0.025306</ixx>
            <ixy>-0.003393</ixy>
            <ixz>0.000608</ixz>
            <iyy>0.084737</iyy>
            <iyz>-0.0002</iyz>
            <izz>0.086016</izz>
          </inertia>
        </inertial>
        <collision name='l_upper_arm_roll_link_geom'>
          <geometry>
            <mesh>
              <uri>model://pr2/meshes/shoulder_v0/upper_arm_roll_L.stl</uri>
              <scale>1 1 1</scale>
            </mesh>
          </geometry>
          <max_contacts>10</max_contacts>
          <surface>
            <contact>
              <ode/>
            </contact>
            <bounce/>
            <friction>
              <torsional>
                <ode/>
              </torsional>
              <ode/>
            </friction>
          </surface>
        </collision>
        <visual name='l_upper_arm_roll_link_geom_visual'>
          <geometry>
            <mesh>
              <uri>model://pr2/meshes/shoulder_v0/upper_arm_roll.stl</uri>
              <scale>1 1 1</scale>
            </mesh>
          </geometry>
        </visual>
        <collision name='l_upper_arm_roll_link_geom_l_upper_arm_link'>
          <geometry>
            <mesh>
              <uri>model://pr2/meshes/upper_arm_v0/upper_arm.stl</uri>
              <scale>1 1 1</scale>
            </mesh>
          </geometry>
          <max_contacts>10</max_contacts>
          <surface>
            <contact>
              <ode/>
            </contact>
            <bounce/>
            <friction>
              <torsional>
                <ode/>
              </torsional>
              <ode/>
            </friction>
          </surface>
        </collision>
        <visual name='l_upper_arm_roll_link_geom_l_upper_arm_link_visual'>
          <geometry>
            <mesh>
              <uri>model://pr2/meshes/upper_arm_v0/upper_arm.dae</uri>
              <scale>1 1 1</scale>
            </mesh>
          </geometry>
        </visual>
        <velocity_decay/>
        <enable_wind>0</enable_wind>
        <kinematic>0</kinematic>
      </link>
      <link name='l_elbow_flex_link'>
        <self_collide>0</self_collide>
        <gravity>0</gravity>
        <pose frame=''>0.45 0.188 0.790675 0 -0 0</pose>
        <inertial>
          <mass>1.90327</mass>
          <pose frame=''>0.01014 0.00032 -0.01211 0 -0 0</pose>
          <inertia>
            <ixx>0.003465</ixx>
            <ixy>4.1e-05</ixy>
            <ixz>0.000432</ixz>
            <iyy>0.004416</iyy>
            <iyz>-4e-05</iyz>
            <izz>0.003592</izz>
          </inertia>
        </inertial>
        <collision name='l_elbow_flex_link_geom'>
          <geometry>
            <mesh>
              <uri>model://pr2/meshes/upper_arm_v0/elbow_flex.stl</uri>
              <scale>1 1 1</scale>
            </mesh>
          </geometry>
          <max_contacts>10</max_contacts>
          <surface>
            <contact>
              <ode/>
            </contact>
            <bounce/>
            <friction>
              <torsional>
                <ode/>
              </torsional>
              <ode/>
            </friction>
          </surface>
        </collision>
        <visual name='l_elbow_flex_link_geom_visual'>
          <geometry>
            <mesh>
              <uri>model://pr2/meshes/upper_arm_v0/elbow_flex.dae</uri>
              <scale>1 1 1</scale>
            </mesh>
          </geometry>
        </visual>
        <velocity_decay/>
        <enable_wind>0</enable_wind>
        <kinematic>0</kinematic>
      </link>
      <link name='l_forearm_roll_link'>
        <self_collide>0</self_collide>
        <gravity>0</gravity>
        <pose frame=''>0.45 0.188 0.790675 0 -0 0</pose>
        <inertial>
          <mass>2.68968</mass>
          <pose frame=''>0.180727 -0.000163 -0.008583 0 -0 0</pose>
          <inertia>
            <ixx>0.014668</ixx>
            <ixy>5.2e-05</ixy>
            <ixz>0.000656</ixz>
            <iyy>0.026279</iyy>
            <iyz>-1.3e-05</iyz>
            <izz>0.027775</izz>
          </inertia>
        </inertial>
        <collision name='l_forearm_roll_link_geom'>
          <geometry>
            <mesh>
              <uri>model://pr2/meshes/upper_arm_v0/forearm_roll_L.stl</uri>
              <scale>1 1 1</scale>
            </mesh>
          </geometry>
          <max_contacts>10</max_contacts>
          <surface>
            <contact>
              <ode/>
            </contact>
            <bounce/>
            <friction>
              <torsional>
                <ode/>
              </torsional>
              <ode/>
            </friction>
          </surface>
        </collision>
        <visual name='l_forearm_roll_link_geom_visual'>
          <geometry>
            <mesh>
              <uri>model://pr2/meshes/upper_arm_v0/forearm_roll.stl</uri>
              <scale>1 1 1</scale>
            </mesh>
          </geometry>
        </visual>
        <collision name='l_forearm_roll_link_geom_l_forearm_link'>
          <geometry>
            <mesh>
              <uri>model://pr2/meshes/forearm_v0/forearm.stl</uri>
              <scale>1 1 1</scale>
            </mesh>
          </geometry>
          <max_contacts>10</max_contacts>
          <surface>
            <contact>
              <ode/>
            </contact>
            <bounce/>
            <friction>
              <torsional>
                <ode/>
              </torsional>
              <ode/>
            </friction>
          </surface>
        </collision>
        <visual name='l_forearm_roll_link_geom_l_forearm_link_visual'>
          <geometry>
            <mesh>
              <uri>model://pr2/meshes/forearm_v0/forearm.dae</uri>
              <scale>1 1 1</scale>
            </mesh>
          </geometry>
        </visual>
        <sensor name='l_forearm_cam_sensor' type='camera'>
          <update_rate>25</update_rate>
          <pose frame=''>0.135 0 0.044 -1.5708 -0.562869 0</pose>
          <camera name='__default__'>
            <horizontal_fov>1.5708</horizontal_fov>
            <image>
              <width>640</width>
              <height>480</height>
              <format>R8G8B8</format>
            </image>
            <clip>
              <near>0.1</near>
              <far>100</far>
            </clip>
          </camera>
        </sensor>
        <velocity_decay/>
        <enable_wind>0</enable_wind>
        <kinematic>0</kinematic>
      </link>
      <link name='l_wrist_flex_link'>
        <self_collide>0</self_collide>
        <gravity>0</gravity>
        <pose frame=''>0.771 0.188 0.790675 0 -0 0</pose>
        <inertial>
          <mass>0.61402</mass>
          <pose frame=''>-0.00157 0 -0.00075 0 -0 0</pose>
          <inertia>
            <ixx>0.000652</ixx>
            <ixy>0</ixy>
            <ixz>3e-06</ixz>
            <iyy>0.000198</iyy>
            <iyz>0</iyz>
            <izz>0.000645</izz>
          </inertia>
        </inertial>
        <collision name='l_wrist_flex_link_geom'>
          <geometry>
            <mesh>
              <uri>model://pr2/meshes/forearm_v0/wrist_flex.stl</uri>
              <scale>1 1 1</scale>
            </mesh>
          </geometry>
          <max_contacts>10</max_contacts>
          <surface>
            <contact>
              <ode/>
            </contact>
            <bounce/>
            <friction>
              <torsional>
                <ode/>
              </torsional>
              <ode/>
            </friction>
          </surface>
        </collision>
        <visual name='l_wrist_flex_link_geom_visual'>
          <geometry>
            <mesh>
              <uri>model://pr2/meshes/forearm_v0/wrist_flex.dae</uri>
              <scale>1 1 1</scale>
            </mesh>
          </geometry>
        </visual>
        <velocity_decay/>
        <enable_wind>0</enable_wind>
        <kinematic>0</kinematic>
      </link>
      <link name='l_wrist_roll_link'>
        <self_collide>0</self_collide>
        <gravity>0</gravity>
        <pose frame=''>0.771 0.188 0.790675 0 -0 0</pose>
        <inertial>
          <mass>0.68107</mass>
          <pose frame=''>0.056408 0.000451 -0.001014 0 -0 0</pose>
          <inertia>
            <ixx>0.011352</ixx>
            <ixy>-1.6e-05</ixy>
            <ixz>-1e-06</ixz>
            <iyy>0.011677</iyy>
            <iyz>-1e-06</iyz>
            <izz>0.011866</izz>
          </inertia>
        </inertial>
        <collision name='l_wrist_roll_link_geom'>
          <geometry>
            <mesh>
              <uri>model://pr2/meshes/forearm_v0/wrist_roll_L.stl</uri>
              <scale>1 1 1</scale>
            </mesh>
          </geometry>
          <max_contacts>10</max_contacts>
          <surface>
            <contact>
              <ode/>
            </contact>
            <bounce/>
            <friction>
              <torsional>
                <ode/>
              </torsional>
              <ode/>
            </friction>
          </surface>
        </collision>
        <visual name='l_wrist_roll_link_geom_visual'>
          <geometry>
            <mesh>
              <uri>model://pr2/meshes/forearm_v0/wrist_roll.stl</uri>
              <scale>1 1 1</scale>
            </mesh>
          </geometry>
        </visual>
        <collision name='l_wrist_roll_link_geom_l_gripper_motor_accelerometer_link'>
          <geometry>
            <box>
              <size>0.001 0.001 0.001</size>
            </box>
          </geometry>
          <max_contacts>10</max_contacts>
          <surface>
            <contact>
              <ode/>
            </contact>
            <bounce/>
            <friction>
              <torsional>
                <ode/>
              </torsional>
              <ode/>
            </friction>
          </surface>
        </collision>
        <visual name='l_wrist_roll_link_geom_l_gripper_motor_accelerometer_link_visual'>
          <geometry>
            <box>
              <size>0.001 0.001 0.001</size>
            </box>
          </geometry>
        </visual>
        <collision name='l_wrist_roll_link_geom_l_gripper_palm_link'>
          <geometry>
            <mesh>
              <uri>model://pr2/meshes/gripper_v0/gripper_palm.stl</uri>
              <scale>1 1 1</scale>
            </mesh>
          </geometry>
          <max_contacts>10</max_contacts>
          <surface>
            <contact>
              <ode/>
            </contact>
            <bounce/>
            <friction>
              <torsional>
                <ode/>
              </torsional>
              <ode/>
            </friction>
          </surface>
        </collision>
        <visual name='l_wrist_roll_link_geom_l_gripper_palm_link_visual'>
          <geometry>
            <mesh>
              <uri>model://pr2/meshes/gripper_v0/gripper_palm.dae</uri>
              <scale>1 1 1</scale>
            </mesh>
          </geometry>
        </visual>
        <velocity_decay/>
        <enable_wind>0</enable_wind>
        <kinematic>0</kinematic>
      </link>
      <link name='l_gripper_l_finger_link'>
        <self_collide>0</self_collide>
        <gravity>0</gravity>
        <pose frame=''>0.84791 0.198 0.790675 0 -0 0</pose>
        <inertial>
          <mass>0.17126</mass>
          <pose frame=''>0.03598 0.0173 -0.00164 0 -0 0</pose>
          <inertia>
            <ixx>7.8e-05</ixx>
            <ixy>1e-06</ixy>
            <ixz>-1e-05</ixz>
            <iyy>0.000197</iyy>
            <iyz>-3e-06</iyz>
            <izz>0.000181</izz>
          </inertia>
        </inertial>
        <collision name='l_gripper_l_finger_link_geom'>
          <geometry>
            <mesh>
              <uri>model://pr2/meshes/gripper_v0/l_finger.stl</uri>
              <scale>1 1 1</scale>
            </mesh>
          </geometry>
          <surface>
            <friction>
              <ode>
                <mu>500</mu>
                <mu2>500</mu2>
                <slip1>0</slip1>
                <slip2>0</slip2>
              </ode>
              <torsional>
                <ode/>
              </torsional>
            </friction>
            <contact>
              <ode>
                <kp>1e+06</kp>
                <kd>1</kd>
                <max_vel>100</max_vel>
                <min_depth>0</min_depth>
              </ode>
            </contact>
            <bounce/>
          </surface>
          <max_contacts>10</max_contacts>
        </collision>
        <visual name='l_gripper_l_finger_link_geom_visual'>
          <geometry>
            <mesh>
              <uri>model://pr2/meshes/gripper_v0/l_finger.dae</uri>
              <scale>1 1 1</scale>
            </mesh>
          </geometry>
        </visual>
        <velocity_decay/>
        <enable_wind>0</enable_wind>
        <kinematic>0</kinematic>
      </link>
      <link name='l_gripper_l_finger_tip_link'>
        <self_collide>0</self_collide>
        <gravity>0</gravity>
        <pose frame=''>0.93928 0.20295 0.790675 0 -0 0</pose>
        <inertial>
          <mass>0.04419</mass>
          <pose frame=''>0.00423 0.00284 0 0 -0 0</pose>
          <inertia>
            <ixx>8e-06</ixx>
            <ixy>6e-06</ixy>
            <ixz>0</ixz>
            <iyy>1e-05</iyy>
            <iyz>0</iyz>
            <izz>1.5e-05</izz>
          </inertia>
        </inertial>
        <collision name='l_gripper_l_finger_tip_link_geom'>
          <geometry>
            <mesh>
              <uri>model://pr2/meshes/gripper_v0/l_finger_tip.stl</uri>
              <scale>1 1 1</scale>
            </mesh>
          </geometry>
          <surface>
            <friction>
              <ode>
                <mu>500</mu>
                <mu2>500</mu2>
                <slip1>0</slip1>
                <slip2>0</slip2>
              </ode>
              <torsional>
                <ode/>
              </torsional>
            </friction>
            <contact>
              <ode>
                <kp>1e+07</kp>
                <kd>1</kd>
                <max_vel>100</max_vel>
                <min_depth>0</min_depth>
              </ode>
            </contact>
            <bounce/>
          </surface>
          <max_contacts>10</max_contacts>
        </collision>
        <visual name='l_gripper_l_finger_tip_link_geom_visual'>
          <geometry>
            <mesh>
              <uri>model://pr2/meshes/gripper_v0/l_finger_tip.dae</uri>
              <scale>1 1 1</scale>
            </mesh>
          </geometry>
        </visual>
        <sensor name='l_gripper_l_finger_tip_contact_sensor' type='contact'>
          <update_rate>100</update_rate>
          <contact>
            <collision>l_gripper_l_finger_tip_link_geom</collision>
            <topic>__default_topic__</topic>
          </contact>
        </sensor>
        <velocity_decay/>
        <enable_wind>0</enable_wind>
        <kinematic>0</kinematic>
      </link>
      <link name='l_gripper_motor_slider_link'>
        <self_collide>0</self_collide>
        <gravity>0</gravity>
        <pose frame=''>0.93928 0.188 0.790675 0 -0 0</pose>
        <inertial>
          <mass>0.01</mass>
          <inertia>
            <ixx>0.001</ixx>
            <ixy>0</ixy>
            <ixz>0</ixz>
            <iyy>0.001</iyy>
            <iyz>0</iyz>
            <izz>0.001</izz>
          </inertia>
        </inertial>
        <velocity_decay/>
        <enable_wind>0</enable_wind>
        <kinematic>0</kinematic>
      </link>
      <link name='l_gripper_motor_screw_link'>
        <self_collide>0</self_collide>
        <gravity>0</gravity>
        <pose frame=''>0.93928 0.188 0.790675 0 -0 0</pose>
        <inertial>
          <mass>0.01</mass>
          <inertia>
            <ixx>0.0001</ixx>
            <ixy>0</ixy>
            <ixz>0</ixz>
            <iyy>0.0001</iyy>
            <iyz>0</iyz>
            <izz>0.0001</izz>
          </inertia>
        </inertial>
        <velocity_decay/>
        <enable_wind>0</enable_wind>
        <kinematic>0</kinematic>
      </link>
      <link name='l_gripper_r_finger_link'>
        <self_collide>0</self_collide>
        <gravity>0</gravity>
        <pose frame=''>0.84791 0.178 0.790675 0 -0 0</pose>
        <inertial>
          <mass>0.17389</mass>
          <pose frame=''>0.03576 -0.01736 -0.00095 0 -0 0</pose>
          <inertia>
            <ixx>7.7e-05</ixx>
            <ixy>-2e-06</ixy>
            <ixz>-8e-06</ixz>
            <iyy>0.000198</iyy>
            <iyz>2e-06</iyz>
            <izz>0.000181</izz>
          </inertia>
        </inertial>
        <collision name='l_gripper_r_finger_link_geom'>
          <pose frame=''>0 0 0 -3.14159 0 0</pose>
          <geometry>
            <mesh>
              <uri>model://pr2/meshes/gripper_v0/l_finger.stl</uri>
              <scale>1 1 1</scale>
            </mesh>
          </geometry>
          <surface>
            <friction>
              <ode>
                <mu>500</mu>
                <mu2>500</mu2>
                <slip1>0</slip1>
                <slip2>0</slip2>
              </ode>
              <torsional>
                <ode/>
              </torsional>
            </friction>
            <contact>
              <ode>
                <kp>1e+06</kp>
                <kd>1</kd>
                <max_vel>100</max_vel>
                <min_depth>0</min_depth>
              </ode>
            </contact>
            <bounce/>
          </surface>
          <max_contacts>10</max_contacts>
        </collision>
        <visual name='l_gripper_r_finger_link_geom_visual'>
          <pose frame=''>0 0 0 -3.14159 0 0</pose>
          <geometry>
            <mesh>
              <uri>model://pr2/meshes/gripper_v0/l_finger.dae</uri>
              <scale>1 1 1</scale>
            </mesh>
          </geometry>
        </visual>
        <velocity_decay/>
        <enable_wind>0</enable_wind>
        <kinematic>0</kinematic>
      </link>
      <link name='l_gripper_r_finger_tip_link'>
        <self_collide>0</self_collide>
        <gravity>0</gravity>
        <pose frame=''>0.93928 0.17305 0.790675 0 -0 0</pose>
        <inertial>
          <mass>0.04419</mass>
          <pose frame=''>0.00423 -0.00284 0 0 -0 0</pose>
          <inertia>
            <ixx>8e-06</ixx>
            <ixy>-6e-06</ixy>
            <ixz>0</ixz>
            <iyy>1e-05</iyy>
            <iyz>0</iyz>
            <izz>1.5e-05</izz>
          </inertia>
        </inertial>
        <collision name='l_gripper_r_finger_tip_link_geom'>
          <pose frame=''>0 0 0 -3.14159 0 0</pose>
          <geometry>
            <mesh>
              <uri>model://pr2/meshes/gripper_v0/l_finger_tip.stl</uri>
              <scale>1 1 1</scale>
            </mesh>
          </geometry>
          <surface>
            <friction>
              <ode>
                <mu>500</mu>
                <mu2>500</mu2>
                <slip1>0</slip1>
                <slip2>0</slip2>
              </ode>
              <torsional>
                <ode/>
              </torsional>
            </friction>
            <contact>
              <ode>
                <kp>1e+07</kp>
                <kd>1</kd>
                <max_vel>100</max_vel>
                <min_depth>0</min_depth>
              </ode>
            </contact>
            <bounce/>
          </surface>
          <max_contacts>10</max_contacts>
        </collision>
        <visual name='l_gripper_r_finger_tip_link_geom_visual'>
          <pose frame=''>0 0 0 -3.14159 0 0</pose>
          <geometry>
            <mesh>
              <uri>model://pr2/meshes/gripper_v0/l_finger_tip.dae</uri>
              <scale>1 1 1</scale>
            </mesh>
          </geometry>
        </visual>
        <sensor name='l_gripper_r_finger_tip_contact_sensor' type='contact'>
          <update_rate>100</update_rate>
          <contact>
            <collision>l_gripper_r_finger_tip_link_geom</collision>
            <topic>__default_topic__</topic>
          </contact>
        </sensor>
        <velocity_decay/>
        <enable_wind>0</enable_wind>
        <kinematic>0</kinematic>
      </link>
      <link name='laser_tilt_mount_link'>
        <self_collide>0</self_collide>
        <pose frame=''>0.04893 0 1.01768 0 -0 0</pose>
        <inertial>
          <mass>0.592</mass>
          <pose frame=''>-0.001134 0.001667 -0.007067 0 -0 0</pose>
          <inertia>
            <ixx>0.001296</ixx>
            <ixy>2.3e-05</ixy>
            <ixz>3.7e-05</ixz>
            <iyy>0.001086</iyy>
            <iyz>3.5e-05</iyz>
            <izz>0.000895</izz>
          </inertia>
        </inertial>
        <collision name='laser_tilt_mount_link_geom'>
          <geometry>
            <mesh>
              <uri>model://pr2/meshes/tilting_laser_v0/tilting_hokuyo_L.stl</uri>
              <scale>1 1 1</scale>
            </mesh>
          </geometry>
          <surface>
            <friction>
              <ode>
                <mu>0</mu>
                <mu2>0</mu2>
                <slip1>0</slip1>
                <slip2>0</slip2>
              </ode>
              <torsional>
                <ode/>
              </torsional>
            </friction>
            <contact>
              <ode>
                <kp>1e+12</kp>
                <kd>10000</kd>
                <max_vel>100</max_vel>
                <min_depth>0</min_depth>
              </ode>
            </contact>
            <bounce/>
          </surface>
          <max_contacts>10</max_contacts>
        </collision>
        <visual name='laser_tilt_mount_link_geom_visual'>
          <geometry>
            <mesh>
              <uri>model://pr2/meshes/tilting_laser_v0/tilting_hokuyo.dae</uri>
              <scale>1 1 1</scale>
            </mesh>
          </geometry>
        </visual>
        <sensor name='laser_tilt' type='ray'>
          <update_rate>40</update_rate>
          <pose frame=''>0 0 0.03 0 -0 0</pose>
          <ray>
            <scan>
              <horizontal>
                <samples>640</samples>
                <resolution>1</resolution>
                <min_angle>-1.39626</min_angle>
                <max_angle>1.39626</max_angle>
              </horizontal>
              <vertical>
                <samples>1</samples>
                <min_angle>0</min_angle>
                <max_angle>0</max_angle>
              </vertical>
            </scan>
            <range>
              <min>0.08</min>
              <max>10</max>
              <resolution>0.01</resolution>
            </range>
          </ray>
        </sensor>
        <velocity_decay/>
        <enable_wind>0</enable_wind>
        <kinematic>0</kinematic>
      </link>
      <link name='r_shoulder_pan_link'>
        <self_collide>0</self_collide>
        <gravity>0</gravity>
        <pose frame=''>-0.05 -0.188 0.790675 0 -0 0</pose>
        <inertial>
          <mass>25.7993</mass>
          <pose frame=''>-0.001201 0.024513 -0.098231 0 -0 0</pose>
          <inertia>
            <ixx>0.866179</ixx>
            <ixy>-0.060865</ixy>
            <ixz>-0.121181</ixz>
            <iyy>0.874217</iyy>
            <iyz>-0.058866</iyz>
            <izz>0.273538</izz>
          </inertia>
        </inertial>
        <collision name='r_shoulder_pan_link_geom'>
          <geometry>
            <mesh>
              <uri>model://pr2/meshes/shoulder_v0/shoulder_pan.stl</uri>
              <scale>1 1 1</scale>
            </mesh>
          </geometry>
          <surface>
            <friction>
              <ode>
                <mu>0</mu>
                <mu2>0</mu2>
                <slip1>0</slip1>
                <slip2>0</slip2>
              </ode>
              <torsional>
                <ode/>
              </torsional>
            </friction>
            <contact>
              <ode>
                <kp>1e+12</kp>
                <kd>10000</kd>
                <max_vel>100</max_vel>
                <min_depth>0</min_depth>
              </ode>
            </contact>
            <bounce/>
          </surface>
          <max_contacts>10</max_contacts>
        </collision>
        <visual name='r_shoulder_pan_link_geom_visual'>
          <geometry>
            <mesh>
              <uri>model://pr2/meshes/shoulder_v0/shoulder_pan.dae</uri>
              <scale>1 1 1</scale>
            </mesh>
          </geometry>
        </visual>
        <velocity_decay/>
        <enable_wind>0</enable_wind>
        <kinematic>0</kinematic>
      </link>
      <link name='r_shoulder_lift_link'>
        <self_collide>0</self_collide>
        <gravity>0</gravity>
        <pose frame=''>0.05 -0.188 0.790675 0 -0 0</pose>
        <inertial>
          <mass>2.74988</mass>
          <pose frame=''>0.02195 -0.02664 -0.03127 0 -0 0</pose>
          <inertia>
            <ixx>0.021056</ixx>
            <ixy>0.004967</ixy>
            <ixz>-0.001948</ixz>
            <iyy>0.021272</iyy>
            <iyz>0.001104</iyz>
            <izz>0.019758</izz>
          </inertia>
        </inertial>
        <collision name='r_shoulder_lift_link_geom'>
          <geometry>
            <mesh>
              <uri>model://pr2/meshes/shoulder_v0/shoulder_lift.stl</uri>
              <scale>1 1 1</scale>
            </mesh>
          </geometry>
          <surface>
            <friction>
              <ode>
                <mu>0</mu>
                <mu2>0</mu2>
                <slip1>0</slip1>
                <slip2>0</slip2>
              </ode>
              <torsional>
                <ode/>
              </torsional>
            </friction>
            <contact>
              <ode>
                <kp>1e+12</kp>
                <kd>10000</kd>
                <max_vel>100</max_vel>
                <min_depth>0</min_depth>
              </ode>
            </contact>
            <bounce/>
          </surface>
          <max_contacts>10</max_contacts>
        </collision>
        <visual name='r_shoulder_lift_link_geom_visual'>
          <geometry>
            <mesh>
              <uri>model://pr2/meshes/shoulder_v0/shoulder_lift.dae</uri>
              <scale>1 1 1</scale>
            </mesh>
          </geometry>
        </visual>
        <velocity_decay/>
        <enable_wind>0</enable_wind>
        <kinematic>0</kinematic>
      </link>
      <link name='r_upper_arm_roll_link'>
        <self_collide>0</self_collide>
        <gravity>0</gravity>
        <pose frame=''>0.05 -0.188 0.790675 0 -0 0</pose>
        <inertial>
          <mass>6.11769</mass>
          <pose frame=''>0.210482 -0.015945 -0.000197 0 -0 0</pose>
          <inertia>
            <ixx>0.025378</ixx>
            <ixy>0.003757</ixy>
            <ixz>-0.000709</ixz>
            <iyy>0.084737</iyy>
            <iyz>-0.000179</iyz>
            <izz>0.086088</izz>
          </inertia>
        </inertial>
        <collision name='r_upper_arm_roll_link_geom'>
          <geometry>
            <mesh>
              <uri>model://pr2/meshes/shoulder_v0/upper_arm_roll_L.stl</uri>
              <scale>1 1 1</scale>
            </mesh>
          </geometry>
          <max_contacts>10</max_contacts>
          <surface>
            <contact>
              <ode/>
            </contact>
            <bounce/>
            <friction>
              <torsional>
                <ode/>
              </torsional>
              <ode/>
            </friction>
          </surface>
        </collision>
        <visual name='r_upper_arm_roll_link_geom_visual'>
          <geometry>
            <mesh>
              <uri>model://pr2/meshes/shoulder_v0/upper_arm_roll.stl</uri>
              <scale>1 1 1</scale>
            </mesh>
          </geometry>
        </visual>
        <collision name='r_upper_arm_roll_link_geom_r_upper_arm_link'>
          <geometry>
            <mesh>
              <uri>model://pr2/meshes/upper_arm_v0/upper_arm.stl</uri>
              <scale>1 1 1</scale>
            </mesh>
          </geometry>
          <max_contacts>10</max_contacts>
          <surface>
            <contact>
              <ode/>
            </contact>
            <bounce/>
            <friction>
              <torsional>
                <ode/>
              </torsional>
              <ode/>
            </friction>
          </surface>
        </collision>
        <visual name='r_upper_arm_roll_link_geom_r_upper_arm_link_visual'>
          <geometry>
            <mesh>
              <uri>model://pr2/meshes/upper_arm_v0/upper_arm.dae</uri>
              <scale>1 1 1</scale>
            </mesh>
          </geometry>
        </visual>
        <velocity_decay/>
        <enable_wind>0</enable_wind>
        <kinematic>0</kinematic>
      </link>
      <link name='r_elbow_flex_link'>
        <self_collide>0</self_collide>
        <gravity>0</gravity>
        <pose frame=''>0.45 -0.188 0.790675 0 -0 0</pose>
        <inertial>
          <mass>1.90327</mass>
          <pose frame=''>0.01014 0.00032 -0.01211 0 -0 0</pose>
          <inertia>
            <ixx>0.003465</ixx>
            <ixy>4.1e-05</ixy>
            <ixz>0.000432</ixz>
            <iyy>0.004416</iyy>
            <iyz>-4e-05</iyz>
            <izz>0.003592</izz>
          </inertia>
        </inertial>
        <collision name='r_elbow_flex_link_geom'>
          <geometry>
            <mesh>
              <uri>model://pr2/meshes/upper_arm_v0/elbow_flex.stl</uri>
              <scale>1 1 1</scale>
            </mesh>
          </geometry>
          <max_contacts>10</max_contacts>
          <surface>
            <contact>
              <ode/>
            </contact>
            <bounce/>
            <friction>
              <torsional>
                <ode/>
              </torsional>
              <ode/>
            </friction>
          </surface>
        </collision>
        <visual name='r_elbow_flex_link_geom_visual'>
          <geometry>
            <mesh>
              <uri>model://pr2/meshes/upper_arm_v0/elbow_flex.dae</uri>
              <scale>1 1 1</scale>
            </mesh>
          </geometry>
        </visual>
        <velocity_decay/>
        <enable_wind>0</enable_wind>
        <kinematic>0</kinematic>
      </link>
      <link name='r_forearm_roll_link'>
        <self_collide>0</self_collide>
        <gravity>0</gravity>
        <pose frame=''>0.45 -0.188 0.790675 0 -0 0</pose>
        <inertial>
          <mass>2.68968</mass>
          <pose frame=''>0.180727 -0.000163 -0.008583 0 -0 0</pose>
          <inertia>
            <ixx>0.014668</ixx>
            <ixy>5.2e-05</ixy>
            <ixz>0.000656</ixz>
            <iyy>0.026279</iyy>
            <iyz>-1.3e-05</iyz>
            <izz>0.027775</izz>
          </inertia>
        </inertial>
        <collision name='r_forearm_roll_link_geom'>
          <geometry>
            <mesh>
              <uri>model://pr2/meshes/upper_arm_v0/forearm_roll_L.stl</uri>
              <scale>1 1 1</scale>
            </mesh>
          </geometry>
          <max_contacts>10</max_contacts>
          <surface>
            <contact>
              <ode/>
            </contact>
            <bounce/>
            <friction>
              <torsional>
                <ode/>
              </torsional>
              <ode/>
            </friction>
          </surface>
        </collision>
        <visual name='r_forearm_roll_link_geom_visual'>
          <geometry>
            <mesh>
              <uri>model://pr2/meshes/upper_arm_v0/forearm_roll.stl</uri>
              <scale>1 1 1</scale>
            </mesh>
          </geometry>
        </visual>
        <collision name='r_forearm_roll_link_geom_r_forearm_link'>
          <geometry>
            <mesh>
              <uri>model://pr2/meshes/forearm_v0/forearm.stl</uri>
              <scale>1 1 1</scale>
            </mesh>
          </geometry>
          <max_contacts>10</max_contacts>
          <surface>
            <contact>
              <ode/>
            </contact>
            <bounce/>
            <friction>
              <torsional>
                <ode/>
              </torsional>
              <ode/>
            </friction>
          </surface>
        </collision>
        <visual name='r_forearm_roll_link_geom_r_forearm_link_visual'>
          <geometry>
            <mesh>
              <uri>model://pr2/meshes/forearm_v0/forearm.dae</uri>
              <scale>1 1 1</scale>
            </mesh>
          </geometry>
        </visual>
        <sensor name='r_forearm_cam_sensor' type='camera'>
          <update_rate>25</update_rate>
          <pose frame=''>0.135 0 0.044 1.5708 -0.562869 -0</pose>
          <camera name='__default__'>
            <horizontal_fov>1.5708</horizontal_fov>
            <image>
              <width>640</width>
              <height>480</height>
              <format>R8G8B8</format>
            </image>
            <clip>
              <near>0.1</near>
              <far>100</far>
            </clip>
          </camera>
        </sensor>
        <velocity_decay/>
        <enable_wind>0</enable_wind>
        <kinematic>0</kinematic>
      </link>
      <link name='r_wrist_flex_link'>
        <self_collide>0</self_collide>
        <gravity>0</gravity>
        <pose frame=''>0.771 -0.188 0.790675 0 -0 0</pose>
        <inertial>
          <mass>0.61402</mass>
          <pose frame=''>-0.00157 0 -0.00075 0 -0 0</pose>
          <inertia>
            <ixx>0.000652</ixx>
            <ixy>0</ixy>
            <ixz>3e-06</ixz>
            <iyy>0.000198</iyy>
            <iyz>0</iyz>
            <izz>0.000645</izz>
          </inertia>
        </inertial>
        <collision name='r_wrist_flex_link_geom'>
          <geometry>
            <mesh>
              <uri>model://pr2/meshes/forearm_v0/wrist_flex.stl</uri>
              <scale>1 1 1</scale>
            </mesh>
          </geometry>
          <max_contacts>10</max_contacts>
          <surface>
            <contact>
              <ode/>
            </contact>
            <bounce/>
            <friction>
              <torsional>
                <ode/>
              </torsional>
              <ode/>
            </friction>
          </surface>
        </collision>
        <visual name='r_wrist_flex_link_geom_visual'>
          <geometry>
            <mesh>
              <uri>model://pr2/meshes/forearm_v0/wrist_flex.dae</uri>
              <scale>1 1 1</scale>
            </mesh>
          </geometry>
        </visual>
        <velocity_decay/>
        <enable_wind>0</enable_wind>
        <kinematic>0</kinematic>
      </link>
      <link name='r_wrist_roll_link'>
        <self_collide>0</self_collide>
        <gravity>0</gravity>
        <pose frame=''>0.771 -0.188 0.790675 0 -0 0</pose>
        <inertial>
          <mass>0.68107</mass>
          <pose frame=''>0.056408 0.000451 -0.001014 0 -0 0</pose>
          <inertia>
            <ixx>0.011352</ixx>
            <ixy>-1.6e-05</ixy>
            <ixz>-1e-06</ixz>
            <iyy>0.011677</iyy>
            <iyz>-1e-06</iyz>
            <izz>0.011866</izz>
          </inertia>
        </inertial>
        <collision name='r_wrist_roll_link_geom'>
          <geometry>
            <mesh>
              <uri>model://pr2/meshes/forearm_v0/wrist_roll_L.stl</uri>
              <scale>1 1 1</scale>
            </mesh>
          </geometry>
          <max_contacts>10</max_contacts>
          <surface>
            <contact>
              <ode/>
            </contact>
            <bounce/>
            <friction>
              <torsional>
                <ode/>
              </torsional>
              <ode/>
            </friction>
          </surface>
        </collision>
        <visual name='r_wrist_roll_link_geom_visual'>
          <geometry>
            <mesh>
              <uri>model://pr2/meshes/forearm_v0/wrist_roll.stl</uri>
              <scale>1 1 1</scale>
            </mesh>
          </geometry>
        </visual>
        <collision name='r_wrist_roll_link_geom_r_gripper_motor_accelerometer_link'>
          <geometry>
            <box>
              <size>0.001 0.001 0.001</size>
            </box>
          </geometry>
          <max_contacts>10</max_contacts>
          <surface>
            <contact>
              <ode/>
            </contact>
            <bounce/>
            <friction>
              <torsional>
                <ode/>
              </torsional>
              <ode/>
            </friction>
          </surface>
        </collision>
        <visual name='r_wrist_roll_link_geom_r_gripper_motor_accelerometer_link_visual'>
          <geometry>
            <box>
              <size>0.001 0.001 0.001</size>
            </box>
          </geometry>
        </visual>
        <collision name='r_wrist_roll_link_geom_r_gripper_palm_link'>
          <geometry>
            <mesh>
              <uri>model://pr2/meshes/gripper_v0/gripper_palm.stl</uri>
              <scale>1 1 1</scale>
            </mesh>
          </geometry>
          <max_contacts>10</max_contacts>
          <surface>
            <contact>
              <ode/>
            </contact>
            <bounce/>
            <friction>
              <torsional>
                <ode/>
              </torsional>
              <ode/>
            </friction>
          </surface>
        </collision>
        <visual name='r_wrist_roll_link_geom_r_gripper_palm_link_visual'>
          <geometry>
            <mesh>
              <uri>model://pr2/meshes/gripper_v0/gripper_palm.dae</uri>
              <scale>1 1 1</scale>
            </mesh>
          </geometry>
        </visual>
        <velocity_decay/>
        <enable_wind>0</enable_wind>
        <kinematic>0</kinematic>
      </link>
      <link name='r_gripper_l_finger_link'>
        <self_collide>0</self_collide>
        <gravity>0</gravity>
        <pose frame=''>0.84791 -0.178 0.790675 0 -0 0</pose>
        <inertial>
          <mass>0.17126</mass>
          <pose frame=''>0.03598 0.0173 -0.00164 0 -0 0</pose>
          <inertia>
            <ixx>7.8e-05</ixx>
            <ixy>1e-06</ixy>
            <ixz>1e-05</ixz>
            <iyy>0.000197</iyy>
            <iyz>-3e-06</iyz>
            <izz>0.000181</izz>
          </inertia>
        </inertial>
        <collision name='r_gripper_l_finger_link_geom'>
          <geometry>
            <mesh>
              <uri>model://pr2/meshes/gripper_v0/l_finger.stl</uri>
              <scale>1 1 1</scale>
            </mesh>
          </geometry>
          <surface>
            <friction>
              <ode>
                <mu>500</mu>
                <mu2>500</mu2>
                <slip1>0</slip1>
                <slip2>0</slip2>
              </ode>
              <torsional>
                <ode/>
              </torsional>
            </friction>
            <contact>
              <ode>
                <kp>1e+06</kp>
                <kd>1</kd>
                <max_vel>100</max_vel>
                <min_depth>0</min_depth>
              </ode>
            </contact>
            <bounce/>
          </surface>
          <max_contacts>10</max_contacts>
        </collision>
        <visual name='r_gripper_l_finger_link_geom_visual'>
          <geometry>
            <mesh>
              <uri>model://pr2/meshes/gripper_v0/l_finger.dae</uri>
              <scale>1 1 1</scale>
            </mesh>
          </geometry>
        </visual>
        <velocity_decay/>
        <enable_wind>0</enable_wind>
        <kinematic>0</kinematic>
      </link>
      <link name='r_gripper_l_finger_tip_link'>
        <self_collide>0</self_collide>
        <gravity>0</gravity>
        <pose frame=''>0.93928 -0.17305 0.790675 0 -0 0</pose>
        <inertial>
          <mass>0.04419</mass>
          <pose frame=''>0.00423 0.00284 0 0 -0 0</pose>
          <inertia>
            <ixx>8e-06</ixx>
            <ixy>6e-06</ixy>
            <ixz>0</ixz>
            <iyy>1e-05</iyy>
            <iyz>0</iyz>
            <izz>1.5e-05</izz>
          </inertia>
        </inertial>
        <collision name='r_gripper_l_finger_tip_link_geom'>
          <geometry>
            <mesh>
              <uri>model://pr2/meshes/gripper_v0/l_finger_tip.stl</uri>
              <scale>1 1 1</scale>
            </mesh>
          </geometry>
          <surface>
            <friction>
              <ode>
                <mu>500</mu>
                <mu2>500</mu2>
                <slip1>0</slip1>
                <slip2>0</slip2>
              </ode>
              <torsional>
                <ode/>
              </torsional>
            </friction>
            <contact>
              <ode>
                <kp>1e+07</kp>
                <kd>1</kd>
                <max_vel>100</max_vel>
                <min_depth>0</min_depth>
              </ode>
            </contact>
            <bounce/>
          </surface>
          <max_contacts>10</max_contacts>
        </collision>
        <visual name='r_gripper_l_finger_tip_link_geom_visual'>
          <geometry>
            <mesh>
              <uri>model://pr2/meshes/gripper_v0/l_finger_tip.dae</uri>
              <scale>1 1 1</scale>
            </mesh>
          </geometry>
        </visual>
        <sensor name='r_gripper_l_finger_tip_contact_sensor' type='contact'>
          <update_rate>100</update_rate>
          <contact>
            <collision>r_gripper_l_finger_tip_link_geom</collision>
            <topic>__default_topic__</topic>
          </contact>
        </sensor>
        <velocity_decay/>
        <enable_wind>0</enable_wind>
        <kinematic>0</kinematic>
      </link>
      <link name='r_gripper_motor_slider_link'>
        <self_collide>0</self_collide>
        <gravity>0</gravity>
        <pose frame=''>0.93928 -0.188 0.790675 0 -0 0</pose>
        <inertial>
          <mass>0.01</mass>
          <inertia>
            <ixx>0.001</ixx>
            <ixy>0</ixy>
            <ixz>0</ixz>
            <iyy>0.001</iyy>
            <iyz>0</iyz>
            <izz>0.001</izz>
          </inertia>
        </inertial>
        <velocity_decay/>
        <enable_wind>0</enable_wind>
        <kinematic>0</kinematic>
      </link>
      <link name='r_gripper_motor_screw_link'>
        <self_collide>0</self_collide>
        <gravity>0</gravity>
        <pose frame=''>0.93928 -0.188 0.790675 0 -0 0</pose>
        <inertial>
          <mass>0.01</mass>
          <inertia>
            <ixx>0.0001</ixx>
            <ixy>0</ixy>
            <ixz>0</ixz>
            <iyy>0.0001</iyy>
            <iyz>0</iyz>
            <izz>0.0001</izz>
          </inertia>
        </inertial>
        <velocity_decay/>
        <enable_wind>0</enable_wind>
        <kinematic>0</kinematic>
      </link>
      <link name='r_gripper_r_finger_link'>
        <self_collide>0</self_collide>
        <gravity>0</gravity>
        <pose frame=''>0.84791 -0.198 0.790675 0 -0 0</pose>
        <inertial>
          <mass>0.17389</mass>
          <pose frame=''>0.03576 -0.01736 -0.00095 0 -0 0</pose>
          <inertia>
            <ixx>7.7e-05</ixx>
            <ixy>-2e-06</ixy>
            <ixz>-8e-06</ixz>
            <iyy>0.000198</iyy>
            <iyz>2e-06</iyz>
            <izz>0.000181</izz>
          </inertia>
        </inertial>
        <collision name='r_gripper_r_finger_link_geom'>
          <pose frame=''>0 0 0 -3.14159 0 0</pose>
          <geometry>
            <mesh>
              <uri>model://pr2/meshes/gripper_v0/l_finger.stl</uri>
              <scale>1 1 1</scale>
            </mesh>
          </geometry>
          <surface>
            <friction>
              <ode>
                <mu>500</mu>
                <mu2>500</mu2>
                <slip1>0</slip1>
                <slip2>0</slip2>
              </ode>
              <torsional>
                <ode/>
              </torsional>
            </friction>
            <contact>
              <ode>
                <kp>1e+06</kp>
                <kd>1</kd>
                <max_vel>100</max_vel>
                <min_depth>0</min_depth>
              </ode>
            </contact>
            <bounce/>
          </surface>
          <max_contacts>10</max_contacts>
        </collision>
        <visual name='r_gripper_r_finger_link_geom_visual'>
          <pose frame=''>0 0 0 -3.14159 0 0</pose>
          <geometry>
            <mesh>
              <uri>model://pr2/meshes/gripper_v0/l_finger.dae</uri>
              <scale>1 1 1</scale>
            </mesh>
          </geometry>
        </visual>
        <velocity_decay/>
        <enable_wind>0</enable_wind>
        <kinematic>0</kinematic>
      </link>
      <link name='r_gripper_r_finger_tip_link'>
        <self_collide>0</self_collide>
        <gravity>0</gravity>
        <pose frame=''>0.93928 -0.20295 0.790675 0 -0 0</pose>
        <inertial>
          <mass>0.04419</mass>
          <pose frame=''>0.00423 -0.00284 0 0 -0 0</pose>
          <inertia>
            <ixx>8e-06</ixx>
            <ixy>-6e-06</ixy>
            <ixz>0</ixz>
            <iyy>1e-05</iyy>
            <iyz>0</iyz>
            <izz>1.5e-05</izz>
          </inertia>
        </inertial>
        <collision name='r_gripper_r_finger_tip_link_geom'>
          <pose frame=''>0 0 0 -3.14159 0 0</pose>
          <geometry>
            <mesh>
              <uri>model://pr2/meshes/gripper_v0/l_finger_tip.stl</uri>
              <scale>1 1 1</scale>
            </mesh>
          </geometry>
          <surface>
            <friction>
              <ode>
                <mu>500</mu>
                <mu2>500</mu2>
                <slip1>0</slip1>
                <slip2>0</slip2>
              </ode>
              <torsional>
                <ode/>
              </torsional>
            </friction>
            <contact>
              <ode>
                <kp>1e+07</kp>
                <kd>1</kd>
                <max_vel>100</max_vel>
                <min_depth>0</min_depth>
              </ode>
            </contact>
            <bounce/>
          </surface>
          <max_contacts>10</max_contacts>
        </collision>
        <visual name='r_gripper_r_finger_tip_link_geom_visual'>
          <pose frame=''>0 0 0 -3.14159 0 0</pose>
          <geometry>
            <mesh>
              <uri>model://pr2/meshes/gripper_v0/l_finger_tip.dae</uri>
              <scale>1 1 1</scale>
            </mesh>
          </geometry>
        </visual>
        <sensor name='r_gripper_r_finger_tip_contact_sensor' type='contact'>
          <update_rate>100</update_rate>
          <contact>
            <collision>r_gripper_r_finger_tip_link_geom</collision>
            <topic>__default_topic__</topic>
          </contact>
        </sensor>
        <velocity_decay/>
        <enable_wind>0</enable_wind>
        <kinematic>0</kinematic>
      </link>
      <link name='torso_lift_motor_screw_link'>
        <self_collide>0</self_collide>
        <pose frame=''>-0.15 0 0.751 0 -0 0</pose>
        <inertial>
          <mass>1</mass>
          <inertia>
            <ixx>0.001</ixx>
            <ixy>0</ixy>
            <ixz>0</ixz>
            <iyy>0.001</iyy>
            <iyz>0</iyz>
            <izz>0.001</izz>
          </inertia>
        </inertial>
        <velocity_decay/>
        <enable_wind>0</enable_wind>
        <kinematic>0</kinematic>
      </link>
      <link name='r_gripper_l_parallel_link'>
        <self_collide>0</self_collide>
        <gravity>0</gravity>
        <pose frame=''>0.82991 -0.157 0.790675 0 -0 0</pose>
        <inertial>
          <mass>0.17126</mass>
          <pose frame=''>0.03598 0.0173 -0.00164 0 -0 0</pose>
          <inertia>
            <ixx>7.8e-05</ixx>
            <ixy>1e-06</ixy>
            <ixz>-1e-05</ixz>
            <iyy>0.000197</iyy>
            <iyz>-3e-06</iyz>
            <izz>0.000181</izz>
          </inertia>
        </inertial>
        <velocity_decay/>
        <enable_wind>0</enable_wind>
        <kinematic>0</kinematic>
      </link>
      <link name='r_gripper_r_parallel_link'>
        <self_collide>0</self_collide>
        <gravity>0</gravity>
        <pose frame=''>0.82991 -0.219 0.790675 0 -0 0</pose>
        <inertial>
          <mass>0.17389</mass>
          <pose frame=''>0.03576 -0.01736 -0.00095 0 -0 0</pose>
          <inertia>
            <ixx>7.7e-05</ixx>
            <ixy>-2e-06</ixy>
            <ixz>-8e-06</ixz>
            <iyy>0.000198</iyy>
            <iyz>2e-06</iyz>
            <izz>0.000181</izz>
          </inertia>
        </inertial>
        <velocity_decay/>
        <enable_wind>0</enable_wind>
        <kinematic>0</kinematic>
      </link>
      <link name='l_gripper_l_parallel_link'>
        <self_collide>0</self_collide>
        <gravity>0</gravity>
        <pose frame=''>0.82991 0.219 0.790675 0 -0 0</pose>
        <inertial>
          <mass>0.17126</mass>
          <pose frame=''>0.03598 0.0173 -0.00164 0 -0 0</pose>
          <inertia>
            <ixx>7.8e-05</ixx>
            <ixy>1e-06</ixy>
            <ixz>1e-05</ixz>
            <iyy>0.000197</iyy>
            <iyz>-3e-06</iyz>
            <izz>0.000181</izz>
          </inertia>
        </inertial>
        <velocity_decay/>
        <enable_wind>0</enable_wind>
        <kinematic>0</kinematic>
      </link>
      <link name='l_gripper_r_parallel_link'>
        <self_collide>0</self_collide>
        <gravity>0</gravity>
        <pose frame=''>0.82991 0.157 0.790675 0 -0 0</pose>
        <inertial>
          <mass>0.17389</mass>
          <pose frame=''>0.03576 -0.01736 -0.00095 0 -0 0</pose>
          <inertia>
            <ixx>7.7e-05</ixx>
            <ixy>-2e-06</ixy>
            <ixz>8e-06</ixz>
            <iyy>0.000198</iyy>
            <iyz>2e-06</iyz>
            <izz>0.000181</izz>
          </inertia>
        </inertial>
        <velocity_decay/>
        <enable_wind>0</enable_wind>
        <kinematic>0</kinematic>
      </link>
      <joint name='bl_caster_rotation_joint' type='revolute'>
        <parent>base_footprint</parent>
        <child>bl_caster_rotation_link</child>
        <axis>
          <xyz>0 0 1</xyz>
          <limit>
            <lower>-1e+16</lower>
            <upper>1e+16</upper>
            <effort>0</effort>
            <velocity>4</velocity>
          </limit>
          <use_parent_model_frame>1</use_parent_model_frame>
          <dynamics>
            <spring_reference>0</spring_reference>
            <spring_stiffness>0</spring_stiffness>
          </dynamics>
        </axis>
      </joint>
      <joint name='bl_caster_l_wheel_joint' type='revolute'>
        <parent>bl_caster_rotation_link</parent>
        <child>bl_caster_l_wheel_link</child>
        <axis>
          <xyz>0 1 0</xyz>
          <limit>
            <lower>-1e+16</lower>
            <upper>1e+16</upper>
            <effort>0</effort>
            <velocity>4</velocity>
          </limit>
          <use_parent_model_frame>1</use_parent_model_frame>
          <dynamics>
            <spring_reference>0</spring_reference>
            <spring_stiffness>0</spring_stiffness>
          </dynamics>
        </axis>
      </joint>
      <joint name='bl_caster_r_wheel_joint' type='revolute'>
        <parent>bl_caster_rotation_link</parent>
        <child>bl_caster_r_wheel_link</child>
        <axis>
          <xyz>0 1 0</xyz>
          <limit>
            <lower>-1e+16</lower>
            <upper>1e+16</upper>
            <effort>0</effort>
            <velocity>4</velocity>
          </limit>
          <use_parent_model_frame>1</use_parent_model_frame>
          <dynamics>
            <spring_reference>0</spring_reference>
            <spring_stiffness>0</spring_stiffness>
          </dynamics>
        </axis>
      </joint>
      <joint name='br_caster_rotation_joint' type='revolute'>
        <parent>base_footprint</parent>
        <child>br_caster_rotation_link</child>
        <axis>
          <xyz>0 0 1</xyz>
          <limit>
            <lower>-1e+16</lower>
            <upper>1e+16</upper>
            <effort>0</effort>
            <velocity>4</velocity>
          </limit>
          <use_parent_model_frame>1</use_parent_model_frame>
          <dynamics>
            <spring_reference>0</spring_reference>
            <spring_stiffness>0</spring_stiffness>
          </dynamics>
        </axis>
      </joint>
      <joint name='br_caster_l_wheel_joint' type='revolute'>
        <parent>br_caster_rotation_link</parent>
        <child>br_caster_l_wheel_link</child>
        <axis>
          <xyz>0 1 0</xyz>
          <limit>
            <lower>-1e+16</lower>
            <upper>1e+16</upper>
            <effort>0</effort>
            <velocity>4</velocity>
          </limit>
          <use_parent_model_frame>1</use_parent_model_frame>
          <dynamics>
            <spring_reference>0</spring_reference>
            <spring_stiffness>0</spring_stiffness>
          </dynamics>
        </axis>
      </joint>
      <joint name='br_caster_r_wheel_joint' type='revolute'>
        <parent>br_caster_rotation_link</parent>
        <child>br_caster_r_wheel_link</child>
        <axis>
          <xyz>0 1 0</xyz>
          <limit>
            <lower>-1e+16</lower>
            <upper>1e+16</upper>
            <effort>0</effort>
            <velocity>4</velocity>
          </limit>
          <use_parent_model_frame>1</use_parent_model_frame>
          <dynamics>
            <spring_reference>0</spring_reference>
            <spring_stiffness>0</spring_stiffness>
          </dynamics>
        </axis>
      </joint>
      <joint name='fl_caster_rotation_joint' type='revolute'>
        <parent>base_footprint</parent>
        <child>fl_caster_rotation_link</child>
        <axis>
          <xyz>0 0 1</xyz>
          <limit>
            <lower>-1e+16</lower>
            <upper>1e+16</upper>
            <effort>0</effort>
            <velocity>4</velocity>
          </limit>
          <use_parent_model_frame>1</use_parent_model_frame>
          <dynamics>
            <spring_reference>0</spring_reference>
            <spring_stiffness>0</spring_stiffness>
          </dynamics>
        </axis>
      </joint>
      <joint name='fl_caster_l_wheel_joint' type='revolute'>
        <parent>fl_caster_rotation_link</parent>
        <child>fl_caster_l_wheel_link</child>
        <axis>
          <xyz>0 1 0</xyz>
          <limit>
            <lower>-1e+16</lower>
            <upper>1e+16</upper>
            <effort>0</effort>
            <velocity>4</velocity>
          </limit>
          <use_parent_model_frame>1</use_parent_model_frame>
          <dynamics>
            <spring_reference>0</spring_reference>
            <spring_stiffness>0</spring_stiffness>
          </dynamics>
        </axis>
      </joint>
      <joint name='fl_caster_r_wheel_joint' type='revolute'>
        <parent>fl_caster_rotation_link</parent>
        <child>fl_caster_r_wheel_link</child>
        <axis>
          <xyz>0 1 0</xyz>
          <limit>
            <lower>-1e+16</lower>
            <upper>1e+16</upper>
            <effort>0</effort>
            <velocity>4</velocity>
          </limit>
          <use_parent_model_frame>1</use_parent_model_frame>
          <dynamics>
            <spring_reference>0</spring_reference>
            <spring_stiffness>0</spring_stiffness>
          </dynamics>
        </axis>
      </joint>
      <joint name='fr_caster_rotation_joint' type='revolute'>
        <parent>base_footprint</parent>
        <child>fr_caster_rotation_link</child>
        <axis>
          <xyz>0 0 1</xyz>
          <limit>
            <lower>-1e+16</lower>
            <upper>1e+16</upper>
            <effort>0</effort>
            <velocity>4</velocity>
          </limit>
          <use_parent_model_frame>1</use_parent_model_frame>
          <dynamics>
            <spring_reference>0</spring_reference>
            <spring_stiffness>0</spring_stiffness>
          </dynamics>
        </axis>
      </joint>
      <joint name='fr_caster_l_wheel_joint' type='revolute'>
        <parent>fr_caster_rotation_link</parent>
        <child>fr_caster_l_wheel_link</child>
        <axis>
          <xyz>0 1 0</xyz>
          <limit>
            <lower>-1e+16</lower>
            <upper>1e+16</upper>
            <effort>0</effort>
            <velocity>4</velocity>
          </limit>
          <use_parent_model_frame>1</use_parent_model_frame>
          <dynamics>
            <spring_reference>0</spring_reference>
            <spring_stiffness>0</spring_stiffness>
          </dynamics>
        </axis>
      </joint>
      <joint name='fr_caster_r_wheel_joint' type='revolute'>
        <parent>fr_caster_rotation_link</parent>
        <child>fr_caster_r_wheel_link</child>
        <axis>
          <xyz>0 1 0</xyz>
          <limit>
            <lower>-1e+16</lower>
            <upper>1e+16</upper>
            <effort>0</effort>
            <velocity>4</velocity>
          </limit>
          <use_parent_model_frame>1</use_parent_model_frame>
          <dynamics>
            <spring_reference>0</spring_reference>
            <spring_stiffness>0</spring_stiffness>
          </dynamics>
        </axis>
      </joint>
      <joint name='torso_lift_joint' type='prismatic'>
        <parent>base_footprint</parent>
        <child>torso_lift_link</child>
        <axis>
          <xyz>0 0 1</xyz>
          <limit>
            <lower>0</lower>
            <upper>0.33</upper>
            <effort>0</effort>
            <velocity>4</velocity>
          </limit>
          <use_parent_model_frame>1</use_parent_model_frame>
          <dynamics>
            <spring_reference>0</spring_reference>
            <spring_stiffness>0</spring_stiffness>
          </dynamics>
        </axis>
      </joint>
      <joint name='head_pan_joint' type='revolute'>
        <parent>torso_lift_link</parent>
        <child>head_pan_link</child>
        <axis>
          <xyz>0 0 1</xyz>
          <dynamics>
            <damping>2</damping>
            <friction>0</friction>
            <spring_reference>0</spring_reference>
            <spring_stiffness>0</spring_stiffness>
          </dynamics>
          <limit>
            <lower>-3.00699</lower>
            <upper>3.00699</upper>
            <effort>0</effort>
            <velocity>4</velocity>
          </limit>
          <use_parent_model_frame>1</use_parent_model_frame>
        </axis>
      </joint>
      <joint name='head_tilt_joint' type='revolute'>
        <parent>head_pan_link</parent>
        <child>head_tilt_link</child>
        <axis>
          <xyz>0 1 0</xyz>
          <dynamics>
            <damping>10</damping>
            <friction>0</friction>
            <spring_reference>0</spring_reference>
            <spring_stiffness>0</spring_stiffness>
          </dynamics>
          <limit>
            <lower>-0.471237</lower>
            <upper>1.39626</upper>
            <effort>0</effort>
            <velocity>4</velocity>
          </limit>
          <use_parent_model_frame>1</use_parent_model_frame>
        </axis>
      </joint>
      <joint name='l_shoulder_pan_joint' type='revolute'>
        <parent>torso_lift_link</parent>
        <child>l_shoulder_pan_link</child>
        <axis>
          <xyz>0 0 1</xyz>
          <dynamics>
            <damping>10</damping>
            <friction>0</friction>
            <spring_reference>0</spring_reference>
            <spring_stiffness>0</spring_stiffness>
          </dynamics>
          <limit>
            <lower>-0.714602</lower>
            <upper>2.2854</upper>
            <effort>0</effort>
            <velocity>4</velocity>
          </limit>
          <use_parent_model_frame>1</use_parent_model_frame>
        </axis>
      </joint>
      <joint name='l_shoulder_lift_joint' type='revolute'>
        <parent>l_shoulder_pan_link</parent>
        <child>l_shoulder_lift_link</child>
        <axis>
          <xyz>0 1 0</xyz>
          <dynamics>
            <damping>10</damping>
            <friction>0</friction>
            <spring_reference>0</spring_reference>
            <spring_stiffness>0</spring_stiffness>
          </dynamics>
          <limit>
            <lower>-0.523601</lower>
            <upper>1.3963</upper>
            <effort>0</effort>
            <velocity>4</velocity>
          </limit>
          <use_parent_model_frame>1</use_parent_model_frame>
        </axis>
      </joint>
      <joint name='l_upper_arm_roll_joint' type='revolute'>
        <parent>l_shoulder_lift_link</parent>
        <child>l_upper_arm_roll_link</child>
        <axis>
          <xyz>1 0 0</xyz>
          <dynamics>
            <damping>0.1</damping>
            <friction>0</friction>
            <spring_reference>0</spring_reference>
            <spring_stiffness>0</spring_stiffness>
          </dynamics>
          <limit>
            <lower>-0.8</lower>
            <upper>3.90001</upper>
            <effort>0</effort>
            <velocity>4</velocity>
          </limit>
          <use_parent_model_frame>1</use_parent_model_frame>
        </axis>
      </joint>
      <joint name='l_elbow_flex_joint' type='revolute'>
        <parent>l_upper_arm_roll_link</parent>
        <child>l_elbow_flex_link</child>
        <axis>
          <xyz>0 1 0</xyz>
          <dynamics>
            <damping>1</damping>
            <friction>0</friction>
            <spring_reference>0</spring_reference>
            <spring_stiffness>0</spring_stiffness>
          </dynamics>
          <limit>
            <lower>-2.32131</lower>
            <upper>0</upper>
            <effort>0</effort>
            <velocity>4</velocity>
          </limit>
          <use_parent_model_frame>1</use_parent_model_frame>
        </axis>
      </joint>
      <joint name='l_forearm_roll_joint' type='revolute'>
        <parent>l_elbow_flex_link</parent>
        <child>l_forearm_roll_link</child>
        <axis>
          <xyz>1 0 0</xyz>
          <dynamics>
            <damping>0.1</damping>
            <friction>0</friction>
            <spring_reference>0</spring_reference>
            <spring_stiffness>0</spring_stiffness>
          </dynamics>
          <limit>
            <lower>-1e+16</lower>
            <upper>1e+16</upper>
            <effort>0</effort>
            <velocity>4</velocity>
          </limit>
          <use_parent_model_frame>1</use_parent_model_frame>
        </axis>
      </joint>
      <joint name='l_wrist_flex_joint' type='revolute'>
        <parent>l_forearm_roll_link</parent>
        <child>l_wrist_flex_link</child>
        <axis>
          <xyz>0 1 0</xyz>
          <dynamics>
            <damping>0.1</damping>
            <friction>0</friction>
            <spring_reference>0</spring_reference>
            <spring_stiffness>0</spring_stiffness>
          </dynamics>
          <limit>
            <lower>-2.18</lower>
            <upper>0</upper>
            <effort>0</effort>
            <velocity>4</velocity>
          </limit>
          <use_parent_model_frame>1</use_parent_model_frame>
        </axis>
      </joint>
      <joint name='l_wrist_roll_joint' type='revolute'>
        <parent>l_wrist_flex_link</parent>
        <child>l_wrist_roll_link</child>
        <axis>
          <xyz>1 0 0</xyz>
          <dynamics>
            <damping>0.1</damping>
            <friction>0</friction>
            <spring_reference>0</spring_reference>
            <spring_stiffness>0</spring_stiffness>
          </dynamics>
          <limit>
            <lower>-1e+16</lower>
            <upper>1e+16</upper>
            <effort>0</effort>
            <velocity>4</velocity>
          </limit>
          <use_parent_model_frame>1</use_parent_model_frame>
        </axis>
      </joint>
      <joint name='l_gripper_l_finger_joint' type='revolute'>
        <parent>l_wrist_roll_link</parent>
        <child>l_gripper_l_finger_link</child>
        <axis>
          <xyz>0 0 1</xyz>
          <dynamics>
            <damping>0.02</damping>
            <friction>0</friction>
            <spring_reference>0</spring_reference>
            <spring_stiffness>0</spring_stiffness>
          </dynamics>
          <limit>
            <lower>0</lower>
            <upper>0.548</upper>
            <effort>0</effort>
            <velocity>4</velocity>
          </limit>
          <use_parent_model_frame>1</use_parent_model_frame>
        </axis>
      </joint>
      <joint name='l_gripper_l_finger_tip_joint' type='revolute'>
        <parent>l_gripper_l_finger_link</parent>
        <child>l_gripper_l_finger_tip_link</child>
        <axis>
          <xyz>0 0 -1</xyz>
          <dynamics>
            <damping>0.001</damping>
            <friction>0</friction>
            <spring_reference>0</spring_reference>
            <spring_stiffness>0</spring_stiffness>
          </dynamics>
          <limit>
            <lower>0</lower>
            <upper>0.548</upper>
            <effort>0</effort>
            <velocity>4</velocity>
          </limit>
          <use_parent_model_frame>1</use_parent_model_frame>
        </axis>
      </joint>
      <joint name='l_gripper_motor_slider_joint' type='prismatic'>
        <parent>l_wrist_roll_link</parent>
        <child>l_gripper_motor_slider_link</child>
        <axis>
          <xyz>1 0 0</xyz>
          <limit>
            <lower>-0.1</lower>
            <upper>0.1</upper>
            <effort>0</effort>
            <velocity>4</velocity>
          </limit>
          <use_parent_model_frame>1</use_parent_model_frame>
          <dynamics>
            <spring_reference>0</spring_reference>
            <spring_stiffness>0</spring_stiffness>
          </dynamics>
        </axis>
      </joint>
      <joint name='l_gripper_motor_screw_joint' type='revolute'>
        <parent>l_gripper_motor_slider_link</parent>
        <child>l_gripper_motor_screw_link</child>
        <axis>
          <xyz>0 1 0</xyz>
          <dynamics>
            <damping>0.0001</damping>
            <friction>0</friction>
            <spring_reference>0</spring_reference>
            <spring_stiffness>0</spring_stiffness>
          </dynamics>
          <limit>
            <lower>-1e+16</lower>
            <upper>1e+16</upper>
            <effort>0</effort>
            <velocity>4</velocity>
          </limit>
          <use_parent_model_frame>1</use_parent_model_frame>
        </axis>
      </joint>
      <joint name='l_gripper_r_finger_joint' type='revolute'>
        <parent>l_wrist_roll_link</parent>
        <child>l_gripper_r_finger_link</child>
        <axis>
          <xyz>0 0 -1</xyz>
          <dynamics>
            <damping>0.02</damping>
            <friction>0</friction>
            <spring_reference>0</spring_reference>
            <spring_stiffness>0</spring_stiffness>
          </dynamics>
          <limit>
            <lower>0</lower>
            <upper>0.548</upper>
            <effort>0</effort>
            <velocity>4</velocity>
          </limit>
          <use_parent_model_frame>1</use_parent_model_frame>
        </axis>
      </joint>
      <joint name='l_gripper_r_finger_tip_joint' type='revolute'>
        <parent>l_gripper_r_finger_link</parent>
        <child>l_gripper_r_finger_tip_link</child>
        <axis>
          <xyz>0 0 1</xyz>
          <dynamics>
            <damping>0.001</damping>
            <friction>0</friction>
            <spring_reference>0</spring_reference>
            <spring_stiffness>0</spring_stiffness>
          </dynamics>
          <limit>
            <lower>0</lower>
            <upper>0.548</upper>
            <effort>0</effort>
            <velocity>4</velocity>
          </limit>
          <use_parent_model_frame>1</use_parent_model_frame>
        </axis>
      </joint>
      <joint name='laser_tilt_mount_joint' type='revolute'>
        <parent>torso_lift_link</parent>
        <child>laser_tilt_mount_link</child>
        <axis>
          <xyz>0 1 0</xyz>
          <dynamics>
            <damping>0.008</damping>
            <friction>0</friction>
            <spring_reference>0</spring_reference>
            <spring_stiffness>0</spring_stiffness>
          </dynamics>
          <limit>
            <lower>-0.7854</lower>
            <upper>1.48353</upper>
            <effort>0</effort>
            <velocity>4</velocity>
          </limit>
          <use_parent_model_frame>1</use_parent_model_frame>
        </axis>
      </joint>
      <joint name='r_shoulder_pan_joint' type='revolute'>
        <parent>torso_lift_link</parent>
        <child>r_shoulder_pan_link</child>
        <axis>
          <xyz>0 0 1</xyz>
          <dynamics>
            <damping>10</damping>
            <friction>0</friction>
            <spring_reference>0</spring_reference>
            <spring_stiffness>0</spring_stiffness>
          </dynamics>
          <limit>
            <lower>-2.2854</lower>
            <upper>0.714602</upper>
            <effort>0</effort>
            <velocity>4</velocity>
          </limit>
          <use_parent_model_frame>1</use_parent_model_frame>
        </axis>
      </joint>
      <joint name='r_shoulder_lift_joint' type='revolute'>
        <parent>r_shoulder_pan_link</parent>
        <child>r_shoulder_lift_link</child>
        <axis>
          <xyz>0 1 0</xyz>
          <dynamics>
            <damping>10</damping>
            <friction>0</friction>
            <spring_reference>0</spring_reference>
            <spring_stiffness>0</spring_stiffness>
          </dynamics>
          <limit>
            <lower>-0.523601</lower>
            <upper>1.3963</upper>
            <effort>0</effort>
            <velocity>4</velocity>
          </limit>
          <use_parent_model_frame>1</use_parent_model_frame>
        </axis>
      </joint>
      <joint name='r_upper_arm_roll_joint' type='revolute'>
        <parent>r_shoulder_lift_link</parent>
        <child>r_upper_arm_roll_link</child>
        <axis>
          <xyz>1 0 0</xyz>
          <dynamics>
            <damping>0.1</damping>
            <friction>0</friction>
            <spring_reference>0</spring_reference>
            <spring_stiffness>0</spring_stiffness>
          </dynamics>
          <limit>
            <lower>-3.90001</lower>
            <upper>0.8</upper>
            <effort>0</effort>
            <velocity>4</velocity>
          </limit>
          <use_parent_model_frame>1</use_parent_model_frame>
        </axis>
      </joint>
      <joint name='r_elbow_flex_joint' type='revolute'>
        <parent>r_upper_arm_roll_link</parent>
        <child>r_elbow_flex_link</child>
        <axis>
          <xyz>0 1 0</xyz>
          <dynamics>
            <damping>1</damping>
            <friction>0</friction>
            <spring_reference>0</spring_reference>
            <spring_stiffness>0</spring_stiffness>
          </dynamics>
          <limit>
            <lower>-2.32131</lower>
            <upper>0</upper>
            <effort>0</effort>
            <velocity>4</velocity>
          </limit>
          <use_parent_model_frame>1</use_parent_model_frame>
        </axis>
      </joint>
      <joint name='r_forearm_roll_joint' type='revolute'>
        <parent>r_elbow_flex_link</parent>
        <child>r_forearm_roll_link</child>
        <axis>
          <xyz>1 0 0</xyz>
          <dynamics>
            <damping>0.1</damping>
            <friction>0</friction>
            <spring_reference>0</spring_reference>
            <spring_stiffness>0</spring_stiffness>
          </dynamics>
          <limit>
            <lower>-1e+16</lower>
            <upper>1e+16</upper>
            <effort>0</effort>
            <velocity>4</velocity>
          </limit>
          <use_parent_model_frame>1</use_parent_model_frame>
        </axis>
      </joint>
      <joint name='r_wrist_flex_joint' type='revolute'>
        <parent>r_forearm_roll_link</parent>
        <child>r_wrist_flex_link</child>
        <axis>
          <xyz>0 1 0</xyz>
          <dynamics>
            <damping>0.1</damping>
            <friction>0</friction>
            <spring_reference>0</spring_reference>
            <spring_stiffness>0</spring_stiffness>
          </dynamics>
          <limit>
            <lower>-2.18</lower>
            <upper>0</upper>
            <effort>0</effort>
            <velocity>4</velocity>
          </limit>
          <use_parent_model_frame>1</use_parent_model_frame>
        </axis>
      </joint>
      <joint name='r_wrist_roll_joint' type='revolute'>
        <parent>r_wrist_flex_link</parent>
        <child>r_wrist_roll_link</child>
        <axis>
          <xyz>1 0 0</xyz>
          <dynamics>
            <damping>0.1</damping>
            <friction>0</friction>
            <spring_reference>0</spring_reference>
            <spring_stiffness>0</spring_stiffness>
          </dynamics>
          <limit>
            <lower>-1e+16</lower>
            <upper>1e+16</upper>
            <effort>0</effort>
            <velocity>4</velocity>
          </limit>
          <use_parent_model_frame>1</use_parent_model_frame>
        </axis>
      </joint>
      <joint name='r_gripper_l_finger_joint' type='revolute'>
        <parent>r_wrist_roll_link</parent>
        <child>r_gripper_l_finger_link</child>
        <axis>
          <xyz>0 0 1</xyz>
          <dynamics>
            <damping>0.02</damping>
            <friction>0</friction>
            <spring_reference>0</spring_reference>
            <spring_stiffness>0</spring_stiffness>
          </dynamics>
          <limit>
            <lower>0</lower>
            <upper>0.548</upper>
            <effort>0</effort>
            <velocity>4</velocity>
          </limit>
          <use_parent_model_frame>1</use_parent_model_frame>
        </axis>
      </joint>
      <joint name='r_gripper_l_finger_tip_joint' type='revolute'>
        <parent>r_gripper_l_finger_link</parent>
        <child>r_gripper_l_finger_tip_link</child>
        <axis>
          <xyz>0 0 -1</xyz>
          <dynamics>
            <damping>0.001</damping>
            <friction>0</friction>
            <spring_reference>0</spring_reference>
            <spring_stiffness>0</spring_stiffness>
          </dynamics>
          <limit>
            <lower>0</lower>
            <upper>0.548</upper>
            <effort>0</effort>
            <velocity>4</velocity>
          </limit>
          <use_parent_model_frame>1</use_parent_model_frame>
        </axis>
      </joint>
      <joint name='r_gripper_motor_slider_joint' type='prismatic'>
        <parent>r_wrist_roll_link</parent>
        <child>r_gripper_motor_slider_link</child>
        <axis>
          <xyz>1 0 0</xyz>
          <dynamics>
            <damping>0</damping>
            <friction>0</friction>
            <spring_reference>0</spring_reference>
            <spring_stiffness>0</spring_stiffness>
          </dynamics>
          <limit>
            <lower>-0.1</lower>
            <upper>0.1</upper>
            <effort>0</effort>
            <velocity>4</velocity>
          </limit>
          <use_parent_model_frame>1</use_parent_model_frame>
        </axis>
      </joint>
      <joint name='r_gripper_motor_screw_joint' type='revolute'>
        <parent>r_gripper_motor_slider_link</parent>
        <child>r_gripper_motor_screw_link</child>
        <axis>
          <xyz>0 1 0</xyz>
          <dynamics>
            <damping>0.0001</damping>
            <friction>0</friction>
            <spring_reference>0</spring_reference>
            <spring_stiffness>0</spring_stiffness>
          </dynamics>
          <limit>
            <lower>-1e+16</lower>
            <upper>1e+16</upper>
            <effort>0</effort>
            <velocity>4</velocity>
          </limit>
          <use_parent_model_frame>1</use_parent_model_frame>
        </axis>
      </joint>
      <joint name='r_gripper_r_finger_joint' type='revolute'>
        <parent>r_wrist_roll_link</parent>
        <child>r_gripper_r_finger_link</child>
        <axis>
          <xyz>0 0 -1</xyz>
          <dynamics>
            <damping>0.02</damping>
            <friction>0</friction>
            <spring_reference>0</spring_reference>
            <spring_stiffness>0</spring_stiffness>
          </dynamics>
          <limit>
            <lower>0</lower>
            <upper>0.548</upper>
            <effort>0</effort>
            <velocity>4</velocity>
          </limit>
          <use_parent_model_frame>1</use_parent_model_frame>
        </axis>
      </joint>
      <joint name='r_gripper_r_finger_tip_joint' type='revolute'>
        <parent>r_gripper_r_finger_link</parent>
        <child>r_gripper_r_finger_tip_link</child>
        <axis>
          <xyz>0 0 1</xyz>
          <dynamics>
            <damping>0.001</damping>
            <friction>0</friction>
            <spring_reference>0</spring_reference>
            <spring_stiffness>0</spring_stiffness>
          </dynamics>
          <limit>
            <lower>0</lower>
            <upper>0.548</upper>
            <effort>0</effort>
            <velocity>4</velocity>
          </limit>
          <use_parent_model_frame>1</use_parent_model_frame>
        </axis>
      </joint>
      <joint name='torso_lift_motor_screw_joint' type='revolute'>
        <parent>base_footprint</parent>
        <child>torso_lift_motor_screw_link</child>
        <axis>
          <xyz>0 0 1</xyz>
          <dynamics>
            <damping>0.0001</damping>
            <friction>0</friction>
            <spring_reference>0</spring_reference>
            <spring_stiffness>0</spring_stiffness>
          </dynamics>
          <limit>
            <lower>-1e+16</lower>
            <upper>1e+16</upper>
            <effort>0</effort>
            <velocity>4</velocity>
          </limit>
          <use_parent_model_frame>1</use_parent_model_frame>
        </axis>
      </joint>
      <joint name='torso_lift_screw_torso_lift_joint' type='screw'>
        <parent>torso_lift_link</parent>
        <child>torso_lift_motor_screw_link</child>
        <thread_pitch>3141.6</thread_pitch>
        <axis>
          <xyz>0 0 1</xyz>
          <dynamics>
            <damping>0</damping>
            <friction>0</friction>
            <spring_reference>0</spring_reference>
            <spring_stiffness>0</spring_stiffness>
          </dynamics>
          <limit>
            <lower>-1e+16</lower>
            <upper>1e+16</upper>
            <effort>0</effort>
            <velocity>4</velocity>
          </limit>
          <use_parent_model_frame>1</use_parent_model_frame>
        </axis>
      </joint>
      <joint name='r_gripper_r_screw_screw_joint' type='screw'>
        <parent>r_gripper_r_finger_tip_link</parent>
        <child>r_gripper_motor_screw_link</child>
        <thread_pitch>-3141.6</thread_pitch>
        <axis>
          <xyz>0 1 0</xyz>
          <dynamics>
            <damping>0</damping>
            <friction>0</friction>
            <spring_reference>0</spring_reference>
            <spring_stiffness>0</spring_stiffness>
          </dynamics>
          <limit>
            <lower>-1e+16</lower>
            <upper>1e+16</upper>
            <effort>0</effort>
            <velocity>4</velocity>
          </limit>
          <use_parent_model_frame>1</use_parent_model_frame>
        </axis>
      </joint>
      <joint name='r_gripper_l_screw_screw_joint' type='screw'>
        <parent>r_gripper_l_finger_tip_link</parent>
        <child>r_gripper_motor_screw_link</child>
        <thread_pitch>3141.6</thread_pitch>
        <axis>
          <xyz>0 1 0</xyz>
          <dynamics>
            <damping>0</damping>
            <friction>0</friction>
            <spring_reference>0</spring_reference>
            <spring_stiffness>0</spring_stiffness>
          </dynamics>
          <limit>
            <lower>-1e+16</lower>
            <upper>1e+16</upper>
            <effort>0</effort>
            <velocity>4</velocity>
          </limit>
          <use_parent_model_frame>1</use_parent_model_frame>
        </axis>
      </joint>
      <joint name='r_gripper_r_parallel_root_joint' type='revolute'>
        <pose frame=''>0.05891 -0.031 0 0 -0 0</pose>
        <parent>r_gripper_r_parallel_link</parent>
        <child>r_wrist_roll_link</child>
        <axis>
          <xyz>0 0 -1</xyz>
          <dynamics>
            <damping>0.2</damping>
            <friction>0</friction>
            <spring_reference>0</spring_reference>
            <spring_stiffness>0</spring_stiffness>
          </dynamics>
          <limit>
            <lower>-1e+16</lower>
            <upper>1e+16</upper>
            <effort>0</effort>
            <velocity>4</velocity>
          </limit>
          <use_parent_model_frame>1</use_parent_model_frame>
        </axis>
      </joint>
      <joint name='r_gripper_l_parallel_root_joint' type='revolute'>
        <pose frame=''>0.05891 0.031 0 0 -0 0</pose>
        <parent>r_gripper_l_parallel_link</parent>
        <child>r_wrist_roll_link</child>
        <axis>
          <xyz>0 0 1</xyz>
          <dynamics>
            <damping>0.2</damping>
            <friction>0</friction>
            <spring_reference>0</spring_reference>
            <spring_stiffness>0</spring_stiffness>
          </dynamics>
          <limit>
            <lower>-1e+16</lower>
            <upper>1e+16</upper>
            <effort>0</effort>
            <velocity>4</velocity>
          </limit>
          <use_parent_model_frame>1</use_parent_model_frame>
        </axis>
      </joint>
      <joint name='r_gripper_r_parallel_tip_joint' type='revolute'>
        <pose frame=''>-0.018 -0.021 0 0 -0 0</pose>
        <parent>r_gripper_r_parallel_link</parent>
        <child>r_gripper_r_finger_tip_link</child>
        <axis>
          <xyz>0 0 1</xyz>
          <dynamics>
            <damping>0</damping>
            <friction>0</friction>
            <spring_reference>0</spring_reference>
            <spring_stiffness>0</spring_stiffness>
          </dynamics>
          <limit>
            <lower>-1e+16</lower>
            <upper>1e+16</upper>
            <effort>0</effort>
            <velocity>4</velocity>
          </limit>
          <use_parent_model_frame>1</use_parent_model_frame>
        </axis>
      </joint>
      <joint name='r_gripper_l_parallel_tip_joint' type='revolute'>
        <pose frame=''>-0.018 0.021 0 0 -0 0</pose>
        <parent>r_gripper_l_parallel_link</parent>
        <child>r_gripper_l_finger_tip_link</child>
        <axis>
          <xyz>0 0 1</xyz>
          <dynamics>
            <damping>0</damping>
            <friction>0</friction>
            <spring_reference>0</spring_reference>
            <spring_stiffness>0</spring_stiffness>
          </dynamics>
          <limit>
            <lower>-1e+16</lower>
            <upper>1e+16</upper>
            <effort>0</effort>
            <velocity>4</velocity>
          </limit>
          <use_parent_model_frame>1</use_parent_model_frame>
        </axis>
      </joint>
      <joint name='r_gripper_joint' type='prismatic'>
        <parent>r_gripper_r_finger_tip_link</parent>
        <child>r_gripper_l_finger_tip_link</child>
        <axis>
          <xyz>0 1 0</xyz>
          <dynamics>
            <damping>0</damping>
            <friction>0</friction>
            <spring_reference>0</spring_reference>
            <spring_stiffness>0</spring_stiffness>
          </dynamics>
          <limit>
            <lower>-1e+16</lower>
            <upper>1e+16</upper>
            <effort>0</effort>
            <velocity>4</velocity>
          </limit>
          <use_parent_model_frame>1</use_parent_model_frame>
        </axis>
      </joint>
      <joint name='l_gripper_r_screw_screw_joint' type='screw'>
        <parent>l_gripper_r_finger_tip_link</parent>
        <child>l_gripper_motor_screw_link</child>
        <thread_pitch>-3141.6</thread_pitch>
        <axis>
          <xyz>0 1 0</xyz>
          <dynamics>
            <damping>0</damping>
            <friction>0</friction>
            <spring_reference>0</spring_reference>
            <spring_stiffness>0</spring_stiffness>
          </dynamics>
          <limit>
            <lower>-1e+16</lower>
            <upper>1e+16</upper>
            <effort>0</effort>
            <velocity>4</velocity>
          </limit>
          <use_parent_model_frame>1</use_parent_model_frame>
        </axis>
      </joint>
      <joint name='l_gripper_l_screw_screw_joint' type='screw'>
        <parent>l_gripper_l_finger_tip_link</parent>
        <child>l_gripper_motor_screw_link</child>
        <thread_pitch>3141.6</thread_pitch>
        <axis>
          <xyz>0 1 0</xyz>
          <dynamics>
            <damping>0</damping>
            <friction>0</friction>
            <spring_reference>0</spring_reference>
            <spring_stiffness>0</spring_stiffness>
          </dynamics>
          <limit>
            <lower>-1e+16</lower>
            <upper>1e+16</upper>
            <effort>0</effort>
            <velocity>4</velocity>
          </limit>
          <use_parent_model_frame>1</use_parent_model_frame>
        </axis>
      </joint>
      <joint name='l_gripper_r_parallel_root_joint' type='revolute'>
        <pose frame=''>0.05891 -0.031 0 0 -0 0</pose>
        <parent>l_gripper_r_parallel_link</parent>
        <child>l_wrist_roll_link</child>
        <axis>
          <xyz>0 0 -1</xyz>
          <dynamics>
            <damping>0.2</damping>
            <friction>0</friction>
            <spring_reference>0</spring_reference>
            <spring_stiffness>0</spring_stiffness>
          </dynamics>
          <limit>
            <lower>-1e+16</lower>
            <upper>1e+16</upper>
            <effort>0</effort>
            <velocity>4</velocity>
          </limit>
          <use_parent_model_frame>1</use_parent_model_frame>
        </axis>
      </joint>
      <joint name='l_gripper_l_parallel_root_joint' type='revolute'>
        <pose frame=''>0.05891 0.031 0 0 -0 0</pose>
        <parent>l_gripper_l_parallel_link</parent>
        <child>l_wrist_roll_link</child>
        <axis>
          <xyz>0 0 1</xyz>
          <dynamics>
            <damping>0.2</damping>
            <friction>0</friction>
            <spring_reference>0</spring_reference>
            <spring_stiffness>0</spring_stiffness>
          </dynamics>
          <limit>
            <lower>-1e+16</lower>
            <upper>1e+16</upper>
            <effort>0</effort>
            <velocity>4</velocity>
          </limit>
          <use_parent_model_frame>1</use_parent_model_frame>
        </axis>
      </joint>
      <joint name='l_gripper_r_parallel_tip_joint' type='revolute'>
        <pose frame=''>-0.018 -0.021 0 0 -0 0</pose>
        <parent>l_gripper_r_parallel_link</parent>
        <child>l_gripper_r_finger_tip_link</child>
        <axis>
          <xyz>0 0 1</xyz>
          <dynamics>
            <damping>0</damping>
            <friction>0</friction>
            <spring_reference>0</spring_reference>
            <spring_stiffness>0</spring_stiffness>
          </dynamics>
          <limit>
            <lower>-1e+16</lower>
            <upper>1e+16</upper>
            <effort>0</effort>
            <velocity>4</velocity>
          </limit>
          <use_parent_model_frame>1</use_parent_model_frame>
        </axis>
      </joint>
      <joint name='l_gripper_l_parallel_tip_joint' type='revolute'>
        <pose frame=''>-0.018 0.021 0 0 -0 0</pose>
        <parent>l_gripper_l_parallel_link</parent>
        <child>l_gripper_l_finger_tip_link</child>
        <axis>
          <xyz>0 0 1</xyz>
          <limit>
            <lower>-1e+16</lower>
            <upper>1e+16</upper>
            <effort>0</effort>
            <velocity>4</velocity>
          </limit>
          <use_parent_model_frame>1</use_parent_model_frame>
          <dynamics>
            <spring_reference>0</spring_reference>
            <spring_stiffness>0</spring_stiffness>
          </dynamics>
        </axis>
      </joint>
      <joint name='l_gripper_joint' type='prismatic'>
        <parent>l_gripper_r_finger_tip_link</parent>
        <child>l_gripper_l_finger_tip_link</child>
        <axis>
          <xyz>0 1 0</xyz>
          <limit>
            <lower>-1e+16</lower>
            <upper>1e+16</upper>
            <effort>0</effort>
            <velocity>4</velocity>
          </limit>
          <use_parent_model_frame>1</use_parent_model_frame>
          <dynamics>
            <spring_reference>0</spring_reference>
            <spring_stiffness>0</spring_stiffness>
          </dynamics>
        </axis>
      </joint>
      <pose frame=''>0.312187 -0.09451 0 0 -0 0</pose>
    </model>
    <state world_name='default'>
      <sim_time>47 351000000</sim_time>
      <real_time>61 638318828</real_time>
      <wall_time>1497395878 170449112</wall_time>
      <iterations>47351</iterations>
      <model name='ground_plane'>
        <pose frame=''>0 0 0 0 -0 0</pose>
        <scale>1 1 1</scale>
        <link name='link'>
          <pose frame=''>0 0 0 0 -0 0</pose>
          <velocity>0 0 0 0 -0 0</velocity>
          <acceleration>0 0 0 0 -0 0</acceleration>
          <wrench>0 0 0 0 -0 0</wrench>
        </link>
      </model>
      <model name='pr2'>
        <pose frame=''>0.335447 -0.076753 -0.004439 -3e-06 -7.5e-05 -0.01537</pose>
        <scale>1 1 1</scale>
        <link name='base_footprint'>
          <pose frame=''>0.335447 -0.076753 -0.004439 -3e-06 -7.5e-05 -0.01537</pose>
          <velocity>0.001707 0.00037 -0.00606 9.9e-05 0.000553 -0.000225</velocity>
          <acceleration>0.089273 0.013729 -11.8558 -0.001559 -0.833205 -0.062843</acceleration>
          <wrench>10.5343 1.62004 -1399 0 -0 0</wrench>
        </link>
        <link name='bl_caster_l_wheel_link'>
          <pose frame=''>0.151009 0.118805 0.074779 3.1414 1.10156 0.846195</pose>
          <velocity>-0.000542 -0.00489 -0.014238 0.066104 -0.047523 -0.112687</velocity>
          <acceleration>2.42904 -2.01828 -26.2766 2.82699 -1.20273 0.678643</acceleration>
          <wrench>1.06965 -0.888771 -11.5711 0 -0 0</wrench>
        </link>
        <link name='bl_caster_r_wheel_link'>
          <pose frame=''>0.077623 0.183747 0.07478 3e-05 -0.971311 -2.29524</pose>
          <velocity>0.005765 0.004263 -0.015816 -0.057633 0.037774 -0.113396</velocity>
          <acceleration>0.653657 -0.530742 -29.3347 -2.72477 0.620667 -1.51804</acceleration>
          <wrench>0.287844 -0.233717 -12.9178 0 -0 0</wrench>
        </link>
        <link name='bl_caster_rotation_link'>
          <pose frame=''>0.114319 0.151273 0.074751 8.1e-05 4.7e-05 -2.29522</pose>
          <velocity>0.001824 0.000435 -0.007853 0.003698 0.004725 -0.112612</velocity>
          <acceleration>0.670209 -0.361634 -15.3485 -0.796583 1.48522 1.17472</acceleration>
          <wrench>2.32769 -1.25598 -53.3064 0 -0 0</wrench>
        </link>
        <link name='br_caster_l_wheel_link'>
          <pose frame=''>0.141647 -0.332924 0.07478 3.14139 1.1259 0.773405</pose>
          <velocity>-0.001384 -0.004964 -0.014026 0.065207 -0.054768 -0.119021</velocity>
          <acceleration>1.94324 -2.2266 -25.8755 -2.20306 -1.46638 0.725567</acceleration>
          <wrench>0.855724 -0.980504 -11.3945 0 -0 0</wrench>
        </link>
        <link name='br_caster_r_wheel_link'>
          <pose frame=''>0.073178 -0.262817 0.07478 3.4e-05 -1.06509 -2.36803</pose>
          <velocity>0.006038 0.004112 -0.015528 -0.056987 0.045088 -0.119755</velocity>
          <acceleration>0.31028 -0.662208 -28.7823 -3.04809 -0.345686 2.00035</acceleration>
          <wrench>0.136635 -0.29161 -12.6746 0 -0 0</wrench>
        </link>
        <link name='br_caster_rotation_link'>
          <pose frame=''>0.107415 -0.297874 0.074752 7.8e-05 5.1e-05 -2.36801</pose>
          <velocity>0.001658 0.000381 -0.007797 0.004145 0.004594 -0.118914</velocity>
          <acceleration>0.519774 -0.515255 -15.1891 0.126374 1.44821 1.35055</acceleration>
          <wrench>1.80522 -1.78952 -52.7529 0 -0 0</wrench>
        </link>
        <link name='fl_caster_l_wheel_link'>
          <pose frame=''>0.57056 0.19285 0.074784 1e-05 0.521074 -0.145262</pose>
          <velocity>0.002136 0.000903 -0.007921 0.004012 0.031231 -0.008467</velocity>
          <acceleration>-0.065446 1.05244 -13.3348 1.59215 -0.225218 0.217843</acceleration>
          <wrench>-0.02882 0.463453 -5.87212 0 -0 0</wrench>
        </link>
        <link name='fl_caster_r_wheel_link'>
          <pose frame=''>0.556374 0.095884 0.074784 -7e-06 0.339113 -0.145268</pose>
          <velocity>0.001249 0.000742 -0.008126 0.006271 0.019964 -0.008722</velocity>
          <acceleration>-0.135503 0.797341 -13.5652 -1.20919 -0.654361 -0.077523</acceleration>
          <wrench>-0.05967 0.351117 -5.97356 0 -0 0</wrench>
        </link>
        <link name='fl_caster_rotation_link'>
          <pose frame=''>0.563466 0.144369 0.074778 1e-05 -7.7e-05 -0.145267</pose>
          <velocity>0.001756 0.000367 -0.006528 -0.00051 0.001224 -0.008527</velocity>
          <acceleration>0.123776 0.075824 -11.9474 0.689617 0.31637 0.019144</acceleration>
          <wrench>0.429885 0.263342 -41.4944 0 -0 0</wrench>
        </link>
        <link name='fr_caster_l_wheel_link'>
          <pose frame=''>0.563115 -0.256221 0.074785 7e-06 0.411623 -0.134126</pose>
          <velocity>0.002251 0.000832 -0.007685 0.004755 0.036307 -0.01423</velocity>
          <acceleration>-0.233517 0.978662 -12.8874 2.21341 -0.269662 0.222838</acceleration>
          <wrench>-0.102832 0.430963 -5.6751 0 -0 0</wrench>
        </link>
        <link name='fr_caster_r_wheel_link'>
          <pose frame=''>0.55001 -0.353339 0.074785 -7e-06 0.247255 -0.134129</pose>
          <velocity>0.000807 0.00078 -0.007858 0.005564 0.01773 -0.014489</velocity>
          <acceleration>-0.304726 0.797219 -13.0514 -1.55448 -0.536064 -0.144669</acceleration>
          <wrench>-0.134189 0.351064 -5.74733 0 -0 0</wrench>
        </link>
        <link name='fr_caster_rotation_link'>
          <pose frame=''>0.556562 -0.304778 0.074779 7e-06 -7.7e-05 -0.134128</pose>
          <velocity>0.001638 0.000369 -0.006491 -0.000201 0.001229 -0.014315</velocity>
          <acceleration>0.067444 0.039929 -11.8332 1.19177 0.430715 -0.017928</acceleration>
          <wrench>0.23424 0.138676 -41.0978 0 -0 0</wrench>
        </link>
        <link name='head_pan_link'>
          <pose frame=''>0.268296 -0.075717 1.16768 0 -7.5e-05 -0.014167</pose>
          <velocity>0.002618 0.000259 -0.004135 -0.000667 0.000556 0.000456</velocity>
          <acceleration>-0.325285 0.12865 -1.28118 -1.37509 -0.994559 -0.294559</acceleration>
          <wrench>-2.06198 0.815511 -8.12143 0 -0 0</wrench>
        </link>
        <link name='head_tilt_link'>
          <pose frame=''>0.336289 -0.076681 1.16768 0 -0.471312 -0.014166</pose>
          <velocity>0.002616 0.000351 -0.004181 -0.000559 0.000708 0.000403</velocity>
          <acceleration>-0.342885 0.182007 -1.22506 -1.30094 -1.53812 -0.56364</acceleration>
          <wrench>-1.82381 0.968094 -6.51607 0 -0 0</wrench>
        </link>
        <link name='l_elbow_flex_link'>
          <pose frame=''>0.788221 0.104203 0.785639 0.000706 -0.086798 -0.01565</pose>
          <velocity>0.002419 0.000393 0.000675 0.003902 0.00224 7.3e-05</velocity>
          <acceleration>0.064349 -0.040925 0.01909 0.868479 -0.346364 -0.353302</acceleration>
          <wrench>0.122474 -0.077892 0.036333 0 -0 0</wrench>
        </link>
        <link name='l_forearm_roll_link'>
          <pose frame=''>0.788221 0.104203 0.785639 0.001457 -0.086798 -0.015652</pose>
          <velocity>0.00245 0.000405 0.000657 5.6e-05 0.002383 5.2e-05</velocity>
          <acceleration>0.132844 0.005397 -0.003117 0.041044 -0.082242 0.16208</acceleration>
          <wrench>0.357309 0.014517 -0.008385 0 -0 0</wrench>
        </link>
        <link name='l_gripper_l_finger_link'>
          <pose frame=''>1.18141 0.108025 0.836807 0.001553 -0.308149 -0.015953</pose>
          <velocity>0.002543 0.000424 5e-06 0.000107 -0.001295 -0.000317</velocity>
          <acceleration>0.279206 -0.003803 0.063296 -0.07276 -0.195634 -1.11802</acceleration>
          <wrench>0.047817 -0.000651 0.01084 0 -0 0</wrench>
        </link>
        <link name='l_gripper_l_finger_tip_link'>
          <pose frame=''>1.26854 0.111585 0.864527 0.001565 -0.30815 -0.015987</pose>
          <velocity>0.002504 0.000395 0.000119 -0.000378 -0.001039 -0.000115</velocity>
          <acceleration>0.253782 -0.053332 0.065473 -1.19355 0.638525 -0.551947</acceleration>
          <wrench>0.011215 -0.002357 0.002893 0 -0 0</wrench>
        </link>
        <link name='l_gripper_l_parallel_link'>
          <pose frame=''>1.16458 0.129297 0.831379 0.001553 -0.308149 -0.015953</pose>
          <velocity>0.002543 0.000424 -1.9e-05 0.000169 -0.001272 -0.000492</velocity>
          <acceleration>0.272029 -0.020953 0.052333 0.308128 -0.134336 -1.50227</acceleration>
          <wrench>0.046588 -0.003588 0.008963 0 -0 0</wrench>
        </link>
        <link name='l_gripper_motor_screw_link'>
          <pose frame=''>1.26831 0.096634 0.864505 0.001559 -0.299006 -0.015973</pose>
          <velocity>0.002515 0.000428 0.000121 4.2e-05 0.000477 9e-06</velocity>
          <acceleration>0.279207 0.044011 0.07673 -0.011244 0.153688 0.021974</acceleration>
          <wrench>0.002792 0.00044 0.000767 0 -0 0</wrench>
        </link>
        <link name='l_gripper_motor_slider_link'>
          <pose frame=''>1.26831 0.096634 0.864505 0.001563 -0.308149 -0.015988</pose>
          <velocity>0.002511 0.000428 0.00012 1.3e-05 -0.001294 2e-05</velocity>
          <acceleration>0.268743 0.041132 0.073208 -0.020694 -0.188236 0.058315</acceleration>
          <wrench>0.002687 0.000411 0.000732 0 -0 0</wrench>
        </link>
        <link name='l_gripper_r_finger_link'>
          <pose frame=''>1.1811 0.088027 0.836778 0.001573 -0.308149 -0.016021</pose>
          <velocity>0.002539 0.000429 3e-06 5.5e-05 -0.001296 -0.00011</velocity>
          <acceleration>0.246891 0.033428 0.05195 -0.026584 -0.202695 -0.465306</acceleration>
          <wrench>0.042932 0.005813 0.009034 0 -0 0</wrench>
        </link>
        <link name='l_gripper_r_finger_tip_link'>
          <pose frame=''>1.26807 0.081683 0.864482 0.001563 -0.308149 -0.015988</pose>
          <velocity>0.002501 0.000421 0.000113 -2.3e-05 -0.001369 5e-05</velocity>
          <acceleration>0.24479 0.017879 0.060581 -0.044462 -0.340589 0.094224</acceleration>
          <wrench>0.010817 0.00079 0.002677 0 -0 0</wrench>
        </link>
        <link name='l_gripper_r_parallel_link'>
          <pose frame=''>1.16362 0.067304 0.831287 0.001574 -0.308149 -0.016022</pose>
          <velocity>0.002538 0.000427 -2.3e-05 -2.9e-05 -0.001298 0.000149</velocity>
          <acceleration>0.239925 0.051688 0.0452 -0.021389 -0.210399 0.265287</acceleration>
          <wrench>0.041721 0.008988 0.00786 0 -0 0</wrench>
        </link>
        <link name='l_shoulder_lift_link'>
          <pose frame=''>0.388271 0.110438 0.786232 -4e-06 0.001484 -0.015588</pose>
          <velocity>0.002331 0.000314 -0.004246 5.4e-05 -0.012749 0.000149</velocity>
          <acceleration>-0.021942 0.001075 -0.807024 -2.89544 0.091393 3.01816</acceleration>
          <wrench>-0.060337 0.002956 -2.21922 0 -0 0</wrench>
        </link>
        <link name='l_shoulder_pan_link'>
          <pose frame=''>0.288283 0.111997 0.786224 -4e-06 -7.6e-05 -0.015588</pose>
          <velocity>0.002329 0.000279 -0.00423 0.000266 0.000815 0.000193</velocity>
          <acceleration>-0.070754 0.000654 -1.03452 0.293357 -0.505549 -0.054666</acceleration>
          <wrench>-1.8254 0.016879 -26.6898 0 -0 0</wrench>
        </link>
        <link name='l_upper_arm_roll_link'>
          <pose frame=''>0.38827 0.110438 0.786231 0.000703 0.001481 -0.015588</pose>
          <velocity>0.002396 0.000338 -0.004135 0.003645 -0.012162 0.000104</velocity>
          <acceleration>0.034306 -0.012885 -0.263246 -2.28629 -1.27644 2.84456</acceleration>
          <wrench>0.209872 -0.078825 -1.61046 0 -0 0</wrench>
        </link>
        <link name='l_wrist_flex_link'>
          <pose frame=''>1.10797 0.099198 0.813466 0.001523 -0.308149 -0.015987</pose>
          <velocity>0.002526 0.000423 -0.000102 -1.4e-05 -0.001375 7.5e-05</velocity>
          <acceleration>0.153906 0.032438 0.012853 -0.025609 -0.397675 0.22036</acceleration>
          <wrench>0.094502 0.019918 0.007892 0 -0 0</wrench>
        </link>
        <link name='l_wrist_roll_link'>
          <pose frame=''>1.10797 0.099198 0.813466 0.001563 -0.308149 -0.015987</pose>
          <velocity>0.00255 0.000425 -9.6e-05 1.1e-05 -0.001295 2.2e-05</velocity>
          <acceleration>0.208985 0.039951 0.03563 -0.02384 -0.184555 0.061629</acceleration>
          <wrench>0.142333 0.027209 0.024266 0 -0 0</wrench>
        </link>
        <link name='laser_tilt_mount_link'>
          <pose frame=''>0.384295 -0.077501 1.01324 -3e-06 -0.159071 -0.01537</pose>
          <velocity>0.002408 0.000238 -0.004311 0.000117 0.001389 -0.000276</velocity>
          <acceleration>-0.354495 -0.018963 -1.33248 -0.01622 -1.38933 -0.146006</acceleration>
          <wrench>-0.209861 -0.011226 -0.788827 0 -0 0</wrench>
        </link>
        <link name='r_elbow_flex_link'>
          <pose frame=''>0.782442 -0.271791 0.785654 0.002056 -0.086546 -0.015846</pose>
          <velocity>0.002273 0.000332 0.000762 -0.003328 0.002806 0.000106</velocity>
          <acceleration>-0.091267 -0.060649 0.193105 -1.32212 0.797783 0.066755</acceleration>
          <wrench>-0.173705 -0.115431 0.367531 0 -0 0</wrench>
        </link>
        <link name='r_forearm_roll_link'>
          <pose frame=''>0.782442 -0.271791 0.785654 0.001474 -0.086546 -0.015846</pose>
          <velocity>0.002269 0.000334 0.000765 0.000206 0.002724 0.000394</velocity>
          <acceleration>-0.08496 -0.02137 0.077545 0.101003 0.714909 0.106822</acceleration>
          <wrench>-0.228514 -0.057478 0.20857 0 -0 0</wrench>
        </link>
        <link name='r_gripper_l_finger_link'>
          <pose frame=''>1.17578 -0.268047 0.836283 0.001584 -0.301887 -0.016143</pose>
          <velocity>0.002334 0.000476 -2.1e-05 -4.1e-05 -0.001138 3.2e-05</velocity>
          <acceleration>-0.032227 -0.005434 -0.01299 -0.108204 -0.031566 -0.223939</acceleration>
          <wrench>-0.005519 -0.000931 -0.002225 0 -0 0</wrench>
        </link>
        <link name='r_gripper_l_finger_tip_link'>
          <pose frame=''>1.26308 -0.264506 0.863457 0.001596 -0.301888 -0.016175</pose>
          <velocity>0.002299 0.000482 7.8e-05 -0.000514 -0.000906 0.00018</velocity>
          <acceleration>-0.042581 -0.011832 -0.015416 -1.06235 0.497837 -0.294661</acceleration>
          <wrench>-0.001882 -0.000523 -0.000681 0 -0 0</wrench>
        </link>
        <link name='r_gripper_l_parallel_link'>
          <pose frame=''>1.15892 -0.246772 0.830963 0.001584 -0.301888 -0.016142</pose>
          <velocity>0.002327 0.00047 -4.6e-05 6.7e-05 -0.001114 -0.000128</velocity>
          <acceleration>-0.045392 -0.026308 -0.022609 0.140856 0.026722 -0.585584</acceleration>
          <wrench>-0.007774 -0.004505 -0.003872 0 -0 0</wrench>
        </link>
        <link name='r_gripper_motor_screw_link'>
          <pose frame=''>1.26285 -0.279457 0.863434 0.00159 -0.293268 -0.016161</pose>
          <velocity>0.002316 0.000513 8.2e-05 -6.2e-05 0.00033 0.000306</velocity>
          <acceleration>-0.012653 0.05185 -0.004032 -0.067469 0.046726 0.203367</acceleration>
          <wrench>-0.000127 0.000518 -4e-05 0 -0 0</wrench>
        </link>
        <link name='r_gripper_motor_slider_link'>
          <pose frame=''>1.26285 -0.279457 0.863434 0.001594 -0.301887 -0.016175</pose>
          <velocity>0.002312 0.000523 8.1e-05 -8.6e-05 -0.001136 0.000321</velocity>
          <acceleration>-0.02149 0.090779 -0.006238 -0.071923 -0.021816 0.246608</acceleration>
          <wrench>-0.000215 0.000908 -6.2e-05 0 -0 0</wrench>
        </link>
        <link name='r_gripper_r_finger_link'>
          <pose frame=''>1.17546 -0.288045 0.836252 0.001603 -0.301887 -0.016207</pose>
          <velocity>0.002337 0.00048 -2.2e-05 -0.000147 -0.001137 0.000502</velocity>
          <acceleration>-0.018607 0.054724 -0.010565 0.055377 -0.023764 1.28851</acceleration>
          <wrench>-0.003236 0.009516 -0.001837 0 -0 0</wrench>
        </link>
        <link name='r_gripper_r_finger_tip_link'>
          <pose frame=''>1.26261 -0.294408 0.863411 0.001593 -0.301888 -0.016173</pose>
          <velocity>0.002308 0.000531 7.8e-05 0.000119 -0.001134 -0.00037</velocity>
          <acceleration>-0.039389 0.125569 -0.015046 -0.5274 -0.84818 -1.73277</acceleration>
          <wrench>-0.001741 0.005549 -0.000665 0 -0 0</wrench>
        </link>
        <link name='r_gripper_r_parallel_link'>
          <pose frame=''>1.15795 -0.308764 0.830869 0.001603 -0.301887 -0.016207</pose>
          <velocity>0.002348 0.000475 -4.2e-05 -0.000159 -0.001121 0.000505</velocity>
          <acceleration>-0.017418 0.05313 -0.013699 -0.281867 0.014972 1.16858</acceleration>
          <wrench>-0.003029 0.009239 -0.002382 0 -0 0</wrench>
        </link>
        <link name='r_shoulder_lift_link'>
          <pose frame=''>0.382491 -0.265525 0.786233 -3e-06 0.001449 -0.015665</pose>
          <velocity>0.002253 0.000302 -0.004318 0 -0.012862 8.9e-05</velocity>
          <acceleration>0.012766 -0.00054 -1.22708 -3.03587 1.01395 3.08021</acceleration>
          <wrench>0.035104 -0.001484 -3.37432 0 -0 0</wrench>
        </link>
        <link name='r_shoulder_pan_link'>
          <pose frame=''>0.282504 -0.263959 0.786226 -3e-06 -7.5e-05 -0.015665</pose>
          <velocity>0.002211 0.000284 -0.004277 9.1e-05 0.000688 0.000105</velocity>
          <acceleration>-0.136446 -0.018865 -1.43764 -0.026327 -0.723587 -0.025235</acceleration>
          <wrench>-3.5202 -0.4867 -37.0901 0 -0 0</wrench>
        </link>
        <link name='r_upper_arm_roll_link'>
          <pose frame=''>0.382491 -0.265525 0.786233 0.002048 0.001448 -0.015665</pose>
          <velocity>0.00225 0.000324 -0.004341 -0.00354 -0.012686 2.6e-05</velocity>
          <acceleration>-0.121756 -0.003269 -0.523898 2.02622 0.697894 2.92322</acceleration>
          <wrench>-0.744864 -0.019998 -3.20504 0 -0 0</wrench>
        </link>
        <link name='r_wrist_flex_link'>
          <pose frame=''>1.1022 -0.276858 0.813401 0.001538 -0.301887 -0.016175</pose>
          <velocity>0.00236 0.000454 -0.000104 0.000151 -0.001135 0.000372</velocity>
          <acceleration>-0.039161 -0.009373 -0.01635 0.01479 -0.010255 0.279452</acceleration>
          <wrench>-0.024046 -0.005755 -0.010039 0 -0 0</wrench>
        </link>
        <link name='r_wrist_roll_link'>
          <pose frame=''>1.1022 -0.276858 0.813401 0.001594 -0.301887 -0.016175</pose>
          <velocity>0.002361 0.000454 -0.000104 -8.3e-05 -0.001136 0.000307</velocity>
          <acceleration>-0.036821 0.003175 -0.01459 -0.05783 -0.023805 0.200977</acceleration>
          <wrench>-0.025078 0.002162 -0.009937 0 -0 0</wrench>
        </link>
        <link name='torso_lift_link'>
          <pose frame=''>0.285393 -0.075981 0.786226 -3e-06 -7.6e-05 -0.01537</pose>
          <velocity>0.002233 0.000298 -0.004395 9.8e-05 0.000868 -0.000256</velocity>
          <acceleration>-0.207103 0.020776 -1.36225 -0.015361 -0.422397 -0.103427</acceleration>
          <wrench>-7.5487 0.757278 -49.6526 0 -0 0</wrench>
        </link>
        <link name='torso_lift_motor_screw_link'>
          <pose frame=''>0.185408 -0.074444 0.746553 -3e-06 -7.5e-05 -0.007592</pose>
          <velocity>0.002218 0.000327 -0.006479 3.9e-05 0.000729 -0.078827</velocity>
          <acceleration>-0.253816 0.022102 -16.0312 -0.120786 -0.346875 1.4124</acceleration>
          <wrench>-0.253816 0.022102 -16.0312 0 -0 0</wrench>
        </link>
      </model>
      <light name='sun'>
        <pose frame=''>0 0 10 0 -0 0</pose>
      </light>
    </state>
    <gui fullscreen='0'>
      <camera name='user_camera'>
        <pose frame=''>5 -5 2 0 0.275643 2.35619</pose>
        <view_controller>orbit</view_controller>
        <projection_type>perspective</projection_type>
      </camera>
    </gui>
  </world>
</sdf>
